package com.hbm.world.dungeon;

import java.util.Random;

import com.hbm.blocks.ModBlocks;
import com.hbm.blocks.generic.DecoBlock;
import com.hbm.blocks.network.energy.CableSwitch;

import net.minecraft.block.Block;
import net.minecraft.block.BlockButton;
import net.minecraft.block.BlockCauldron;
import net.minecraft.block.BlockChest;
import net.minecraft.block.BlockDispenser;
import net.minecraft.block.BlockHalfWoodSlab;
import net.minecraft.block.BlockLadder;
import net.minecraft.block.BlockLever;
import net.minecraft.block.BlockPlanks;
import net.minecraft.block.BlockSlab;
import net.minecraft.block.BlockStainedGlass;
import net.minecraft.block.BlockStainedHardenedClay;
import net.minecraft.block.BlockStairs;
import net.minecraft.block.BlockStoneSlab;
import net.minecraft.block.BlockTorch;
import net.minecraft.block.BlockTrapDoor;
import net.minecraft.init.Blocks;
import net.minecraft.item.EnumDyeColor;
import net.minecraft.util.EnumFacing;
import net.minecraft.util.math.BlockPos;
import net.minecraft.world.World;

public class Ruin002 {

	Block Block1 = ModBlocks.brick_concrete;
	Block Block4 = ModBlocks.deco_steel;
	Block Block5 = ModBlocks.steel_wall;

	public boolean generate_r00(World world, Random rand, int x, int y, int z) {

		world.setBlockState(new BlockPos(x + 0, y + 5, z + 4), Block1.getDefaultState(), 3);
		world.setBlockState(new BlockPos(x + 1, y + 5, z + 4), Block1.getDefaultState(), 3);
		world.setBlockState(new BlockPos(x + 2, y + 5, z + 4), Block1.getDefaultState(), 3);
		world.setBlockState(new BlockPos(x + 3, y + 5, z + 4), Block1.getDefaultState(), 3);
		world.setBlockState(new BlockPos(x + 4, y + 5, z + 4), Block1.getDefaultState(), 3);
		world.setBlockState(new BlockPos(x + 5, y + 5, z + 4), Block1.getDefaultState(), 3);
		world.setBlockState(new BlockPos(x + 6, y + 5, z + 4), Block1.getDefaultState(), 3);
		world.setBlockState(new BlockPos(x + 7, y + 5, z + 4), Block1.getDefaultState(), 3);
		world.setBlockState(new BlockPos(x + 8, y + 5, z + 4), Block1.getDefaultState(), 3);
		world.setBlockState(new BlockPos(x + 9, y + 5, z + 4), Block1.getDefaultState(), 3);
		world.setBlockState(new BlockPos(x + 10, y + 5, z + 4), Block1.getDefaultState(), 3);
		world.setBlockState(new BlockPos(x + 11, y + 5, z + 4), Block1.getDefaultState(), 3);
		world.setBlockState(new BlockPos(x + 12, y + 5, z + 4), Block1.getDefaultState(), 3);
		world.setBlockState(new BlockPos(x + 0, y + 5, z + 5), Block1.getDefaultState(), 3);
		world.setBlockState(new BlockPos(x + 1, y + 5, z + 5), Blocks.AIR.getDefaultState(), 3);
		world.setBlockState(new BlockPos(x + 2, y + 5, z + 5), Blocks.AIR.getDefaultState(), 3);
		world.setBlockState(new BlockPos(x + 3, y + 5, z + 5), Blocks.AIR.getDefaultState(), 3);
		world.setBlockState(new BlockPos(x + 4, y + 5, z + 5), Blocks.AIR.getDefaultState(), 3);
		world.setBlockState(new BlockPos(x + 5, y + 5, z + 5), Blocks.CHEST.getDefaultState().withProperty(BlockChest.FACING, EnumFacing.SOUTH), 3);
		world.setBlockState(new BlockPos(x + 6, y + 5, z + 5), Blocks.CHEST.getDefaultState().withProperty(BlockChest.FACING, EnumFacing.SOUTH), 3);
		world.setBlockState(new BlockPos(x + 7, y + 5, z + 5), Blocks.AIR.getDefaultState(), 3);
		world.setBlockState(new BlockPos(x + 8, y + 5, z + 5), Blocks.AIR.getDefaultState(), 3);
		world.setBlockState(new BlockPos(x + 12, y + 5, z + 5), Block1.getDefaultState(), 3);
		world.setBlockState(new BlockPos(x + 0, y + 5, z + 6), Block1.getDefaultState(), 3);
		world.setBlockState(new BlockPos(x + 1, y + 5, z + 6), ModBlocks.red_cable.getDefaultState(), 3);
		world.setBlockState(new BlockPos(x + 2, y + 5, z + 6), Blocks.AIR.getDefaultState(), 3);
		world.setBlockState(new BlockPos(x + 3, y + 5, z + 6), Blocks.AIR.getDefaultState(), 3);
		world.setBlockState(new BlockPos(x + 4, y + 5, z + 6), Blocks.AIR.getDefaultState(), 3);
		world.setBlockState(new BlockPos(x + 5, y + 5, z + 6), Blocks.AIR.getDefaultState(), 3);
		world.setBlockState(new BlockPos(x + 6, y + 5, z + 6), Blocks.AIR.getDefaultState(), 3);
		world.setBlockState(new BlockPos(x + 7, y + 5, z + 6), Blocks.AIR.getDefaultState(), 3);
		world.setBlockState(new BlockPos(x + 8, y + 5, z + 6), Blocks.AIR.getDefaultState(), 3);
		world.setBlockState(new BlockPos(x + 12, y + 5, z + 6), Block1.getDefaultState(), 3);
		world.setBlockState(new BlockPos(x + 0, y + 5, z + 7), Block1.getDefaultState(), 3);
		world.setBlockState(new BlockPos(x + 1, y + 5, z + 7), Blocks.AIR.getDefaultState(), 3);
		world.setBlockState(new BlockPos(x + 2, y + 5, z + 7), Blocks.AIR.getDefaultState(), 3);
		world.setBlockState(new BlockPos(x + 3, y + 5, z + 7), Blocks.AIR.getDefaultState(), 3);
		world.setBlockState(new BlockPos(x + 4, y + 5, z + 7), Blocks.AIR.getDefaultState(), 3);
		world.setBlockState(new BlockPos(x + 5, y + 5, z + 7), Blocks.AIR.getDefaultState(), 3);
		world.setBlockState(new BlockPos(x + 6, y + 5, z + 7), Blocks.AIR.getDefaultState(), 3);
		world.setBlockState(new BlockPos(x + 7, y + 5, z + 7), Blocks.AIR.getDefaultState(), 3);
		world.setBlockState(new BlockPos(x + 8, y + 5, z + 7), Blocks.AIR.getDefaultState(), 3);
		world.setBlockState(new BlockPos(x + 12, y + 5, z + 7), Block1.getDefaultState(), 3);
		world.setBlockState(new BlockPos(x + 0, y + 5, z + 8), Block1.getDefaultState(), 3);
		world.setBlockState(new BlockPos(x + 1, y + 5, z + 8), Blocks.AIR.getDefaultState(), 3);
		world.setBlockState(new BlockPos(x + 2, y + 5, z + 8), Blocks.AIR.getDefaultState(), 3);
		world.setBlockState(new BlockPos(x + 3, y + 5, z + 8), Blocks.AIR.getDefaultState(), 3);
		world.setBlockState(new BlockPos(x + 4, y + 5, z + 8), Blocks.AIR.getDefaultState(), 3);
		world.setBlockState(new BlockPos(x + 5, y + 5, z + 8), Blocks.AIR.getDefaultState(), 3);
		world.setBlockState(new BlockPos(x + 6, y + 5, z + 8), Blocks.AIR.getDefaultState(), 3);
		world.setBlockState(new BlockPos(x + 7, y + 5, z + 8), Blocks.AIR.getDefaultState(), 3);
		world.setBlockState(new BlockPos(x + 8, y + 5, z + 8), Blocks.AIR.getDefaultState(), 3);
		world.setBlockState(new BlockPos(x + 12, y + 5, z + 8), Block1.getDefaultState(), 3);
		world.setBlockState(new BlockPos(x + 0, y + 5, z + 9), Block1.getDefaultState(), 3);
		world.setBlockState(new BlockPos(x + 1, y + 5, z + 9), Blocks.AIR.getDefaultState(), 3);
		world.setBlockState(new BlockPos(x + 2, y + 5, z + 9), Blocks.AIR.getDefaultState(), 3);
		world.setBlockState(new BlockPos(x + 3, y + 5, z + 9), Blocks.AIR.getDefaultState(), 3);
		world.setBlockState(new BlockPos(x + 4, y + 5, z + 9), Blocks.AIR.getDefaultState(), 3);
		world.setBlockState(new BlockPos(x + 5, y + 5, z + 9), Blocks.AIR.getDefaultState(), 3);
		world.setBlockState(new BlockPos(x + 6, y + 5, z + 9), Blocks.AIR.getDefaultState(), 3);
		world.setBlockState(new BlockPos(x + 7, y + 5, z + 9), Blocks.AIR.getDefaultState(), 3);
		world.setBlockState(new BlockPos(x + 8, y + 5, z + 9), Blocks.AIR.getDefaultState(), 3);
		world.setBlockState(new BlockPos(x + 12, y + 5, z + 9), Block1.getDefaultState(), 3);
		world.setBlockState(new BlockPos(x + 0, y + 5, z + 10), Block1.getDefaultState(), 3);
		world.setBlockState(new BlockPos(x + 1, y + 5, z + 10), ModBlocks.red_cable.getDefaultState(), 3);
		world.setBlockState(new BlockPos(x + 2, y + 5, z + 10), Blocks.AIR.getDefaultState(), 3);
		world.setBlockState(new BlockPos(x + 3, y + 5, z + 10), Blocks.AIR.getDefaultState(), 3);
		world.setBlockState(new BlockPos(x + 4, y + 5, z + 10), Blocks.AIR.getDefaultState(), 3);
		world.setBlockState(new BlockPos(x + 5, y + 5, z + 10), Blocks.AIR.getDefaultState(), 3);
		world.setBlockState(new BlockPos(x + 6, y + 5, z + 10), Blocks.AIR.getDefaultState(), 3);
		world.setBlockState(new BlockPos(x + 7, y + 5, z + 10), Blocks.AIR.getDefaultState(), 3);
		world.setBlockState(new BlockPos(x + 8, y + 5, z + 10), Blocks.AIR.getDefaultState(), 3);
		world.setBlockState(new BlockPos(x + 9, y + 5, z + 10), Blocks.AIR.getDefaultState(), 3);
		world.setBlockState(new BlockPos(x + 10, y + 5, z + 10), Blocks.AIR.getDefaultState(), 3);
		world.setBlockState(new BlockPos(x + 11, y + 5, z + 10), Blocks.AIR.getDefaultState(), 3);
		world.setBlockState(new BlockPos(x + 12, y + 5, z + 10), Block1.getDefaultState(), 3);
		world.setBlockState(new BlockPos(x + 0, y + 5, z + 11), Block1.getDefaultState(), 3);
		world.setBlockState(new BlockPos(x + 1, y + 5, z + 11), Blocks.AIR.getDefaultState(), 3);
		world.setBlockState(new BlockPos(x + 2, y + 5, z + 11), Blocks.AIR.getDefaultState(), 3);
		world.setBlockState(new BlockPos(x + 3, y + 5, z + 11), Blocks.AIR.getDefaultState(), 3);
		world.setBlockState(new BlockPos(x + 4, y + 5, z + 11), Blocks.AIR.getDefaultState(), 3);
		world.setBlockState(new BlockPos(x + 5, y + 5, z + 11), Blocks.AIR.getDefaultState(), 3);
		world.setBlockState(new BlockPos(x + 6, y + 5, z + 11), Blocks.AIR.getDefaultState(), 3);
		world.setBlockState(new BlockPos(x + 7, y + 5, z + 11), Blocks.AIR.getDefaultState(), 3);
		world.setBlockState(new BlockPos(x + 8, y + 5, z + 11), Blocks.AIR.getDefaultState(), 3);
		world.setBlockState(new BlockPos(x + 9, y + 5, z + 11), Blocks.AIR.getDefaultState(), 3);
		world.setBlockState(new BlockPos(x + 10, y + 5, z + 11), Blocks.AIR.getDefaultState(), 3);
		world.setBlockState(new BlockPos(x + 11, y + 5, z + 11), Blocks.AIR.getDefaultState(), 3);
		world.setBlockState(new BlockPos(x + 12, y + 5, z + 11), Block1.getDefaultState(), 3);
		world.setBlockState(new BlockPos(x + 0, y + 5, z + 12), Block1.getDefaultState(), 3);
		world.setBlockState(new BlockPos(x + 1, y + 5, z + 12), Blocks.AIR.getDefaultState(), 3);
		world.setBlockState(new BlockPos(x + 2, y + 5, z + 12), Blocks.AIR.getDefaultState(), 3);
		world.setBlockState(new BlockPos(x + 3, y + 5, z + 12), Blocks.AIR.getDefaultState(), 3);
		world.setBlockState(new BlockPos(x + 4, y + 5, z + 12), Blocks.AIR.getDefaultState(), 3);
		world.setBlockState(new BlockPos(x + 5, y + 5, z + 12), Blocks.AIR.getDefaultState(), 3);
		world.setBlockState(new BlockPos(x + 6, y + 5, z + 12), Blocks.AIR.getDefaultState(), 3);
		world.setBlockState(new BlockPos(x + 7, y + 5, z + 12), Blocks.AIR.getDefaultState(), 3);
		world.setBlockState(new BlockPos(x + 8, y + 5, z + 12), Blocks.AIR.getDefaultState(), 3);
		world.setBlockState(new BlockPos(x + 9, y + 5, z + 12), Blocks.AIR.getDefaultState(), 3);
		world.setBlockState(new BlockPos(x + 11, y + 5, z + 12), Block1.getDefaultState(), 3);
		world.setBlockState(new BlockPos(x + 12, y + 5, z + 12), Block1.getDefaultState(), 3);
		world.setBlockState(new BlockPos(x + 0, y + 5, z + 13), Block1.getDefaultState(), 3);
		world.setBlockState(new BlockPos(x + 1, y + 5, z + 13), Blocks.WEB.getDefaultState(), 3);
		world.setBlockState(new BlockPos(x + 2, y + 5, z + 13), Blocks.AIR.getDefaultState(), 3);
		world.setBlockState(new BlockPos(x + 3, y + 5, z + 13), Blocks.AIR.getDefaultState(), 3);
		world.setBlockState(new BlockPos(x + 4, y + 5, z + 13), Blocks.AIR.getDefaultState(), 3);
		world.setBlockState(new BlockPos(x + 5, y + 5, z + 13), Blocks.AIR.getDefaultState(), 3);
		world.setBlockState(new BlockPos(x + 6, y + 5, z + 13), Blocks.AIR.getDefaultState(), 3);
		world.setBlockState(new BlockPos(x + 7, y + 5, z + 13), Blocks.AIR.getDefaultState(), 3);
		world.setBlockState(new BlockPos(x + 8, y + 5, z + 13), Blocks.AIR.getDefaultState(), 3);
		world.setBlockState(new BlockPos(x + 9, y + 5, z + 13), Blocks.AIR.getDefaultState(), 3);
		world.setBlockState(new BlockPos(x + 10, y + 5, z + 13), Block1.getDefaultState(), 3);
		world.setBlockState(new BlockPos(x + 11, y + 5, z + 13), Block1.getDefaultState(), 3);
		world.setBlockState(new BlockPos(x + 12, y + 5, z + 13), Block1.getDefaultState(), 3);
		world.setBlockState(new BlockPos(x + 1, y + 5, z + 14), Block1.getDefaultState(), 3);
		world.setBlockState(new BlockPos(x + 2, y + 5, z + 14), Block1.getDefaultState(), 3);
		world.setBlockState(new BlockPos(x + 3, y + 5, z + 14), Block1.getDefaultState(), 3);
		world.setBlockState(new BlockPos(x + 4, y + 5, z + 14), Block1.getDefaultState(), 3);
		world.setBlockState(new BlockPos(x + 5, y + 5, z + 14), Block1.getDefaultState(), 3);
		world.setBlockState(new BlockPos(x + 6, y + 5, z + 14), Block1.getDefaultState(), 3);
		world.setBlockState(new BlockPos(x + 7, y + 5, z + 14), Block1.getDefaultState(), 3);
		world.setBlockState(new BlockPos(x + 8, y + 5, z + 14), Block1.getDefaultState(), 3);
		world.setBlockState(new BlockPos(x + 9, y + 5, z + 14), Block1.getDefaultState(), 3);
		world.setBlockState(new BlockPos(x + 10, y + 5, z + 14), Block1.getDefaultState(), 3);
		world.setBlockState(new BlockPos(x + 11, y + 5, z + 14), Block1.getDefaultState(), 3);
		world.setBlockState(new BlockPos(x + 0, y + 6, z + 4), Block1.getDefaultState(), 3);
		world.setBlockState(new BlockPos(x + 1, y + 6, z + 4), Block1.getDefaultState(), 3);
		world.setBlockState(new BlockPos(x + 2, y + 6, z + 4), Block1.getDefaultState(), 3);
		world.setBlockState(new BlockPos(x + 3, y + 6, z + 4), Block1.getDefaultState(), 3);
		world.setBlockState(new BlockPos(x + 4, y + 6, z + 4), Block1.getDefaultState(), 3);
		world.setBlockState(new BlockPos(x + 5, y + 6, z + 4), Block1.getDefaultState(), 3);
		world.setBlockState(new BlockPos(x + 6, y + 6, z + 4), Block1.getDefaultState(), 3);
		world.setBlockState(new BlockPos(x + 7, y + 6, z + 4), Block1.getDefaultState(), 3);
		world.setBlockState(new BlockPos(x + 8, y + 6, z + 4), Block1.getDefaultState(), 3);
		world.setBlockState(new BlockPos(x + 9, y + 6, z + 4), Block1.getDefaultState(), 3);
		world.setBlockState(new BlockPos(x + 10, y + 6, z + 4), Block1.getDefaultState(), 3);
		world.setBlockState(new BlockPos(x + 11, y + 6, z + 4), Block1.getDefaultState(), 3);
		world.setBlockState(new BlockPos(x + 12, y + 6, z + 4), Block1.getDefaultState(), 3);
		world.setBlockState(new BlockPos(x + 0, y + 6, z + 5), Block1.getDefaultState(), 3);
		world.setBlockState(new BlockPos(x + 1, y + 6, z + 5), Blocks.AIR.getDefaultState(), 3);
		world.setBlockState(new BlockPos(x + 2, y + 6, z + 5), Blocks.AIR.getDefaultState(), 3);
		world.setBlockState(new BlockPos(x + 3, y + 6, z + 5), Blocks.AIR.getDefaultState(), 3);
		world.setBlockState(new BlockPos(x + 4, y + 6, z + 5), Blocks.AIR.getDefaultState(), 3);
		world.setBlockState(new BlockPos(x + 5, y + 6, z + 5), Blocks.AIR.getDefaultState(), 3);
		world.setBlockState(new BlockPos(x + 6, y + 6, z + 5), Blocks.AIR.getDefaultState(), 3);
		world.setBlockState(new BlockPos(x + 7, y + 6, z + 5), Blocks.AIR.getDefaultState(), 3);
		world.setBlockState(new BlockPos(x + 8, y + 6, z + 5), Blocks.AIR.getDefaultState(), 3);
		world.setBlockState(new BlockPos(x + 9, y + 6, z + 5), Blocks.AIR.getDefaultState(), 3);
		world.setBlockState(new BlockPos(x + 10, y + 6, z + 5), Blocks.WEB.getDefaultState(), 3);
		world.setBlockState(new BlockPos(x + 11, y + 6, z + 5), Blocks.WEB.getDefaultState(), 3);
		world.setBlockState(new BlockPos(x + 12, y + 6, z + 5), Block1.getDefaultState(), 3);
		world.setBlockState(new BlockPos(x + 0, y + 6, z + 6), Block1.getDefaultState(), 3);
		world.setBlockState(new BlockPos(x + 1, y + 6, z + 6), ModBlocks.red_cable.getDefaultState(), 3);
		world.setBlockState(new BlockPos(x + 2, y + 6, z + 6), Blocks.AIR.getDefaultState(), 3);
		world.setBlockState(new BlockPos(x + 3, y + 6, z + 6), Blocks.AIR.getDefaultState(), 3);
		world.setBlockState(new BlockPos(x + 4, y + 6, z + 6), Blocks.AIR.getDefaultState(), 3);
		world.setBlockState(new BlockPos(x + 5, y + 6, z + 6), Blocks.AIR.getDefaultState(), 3);
		world.setBlockState(new BlockPos(x + 6, y + 6, z + 6), Blocks.AIR.getDefaultState(), 3);
		world.setBlockState(new BlockPos(x + 7, y + 6, z + 6), Blocks.AIR.getDefaultState(), 3);
		world.setBlockState(new BlockPos(x + 8, y + 6, z + 6), Blocks.AIR.getDefaultState(), 3);
		world.setBlockState(new BlockPos(x + 9, y + 6, z + 6), Blocks.AIR.getDefaultState(), 3);
		world.setBlockState(new BlockPos(x + 10, y + 6, z + 6), Blocks.AIR.getDefaultState(), 3);
		world.setBlockState(new BlockPos(x + 11, y + 6, z + 6), Blocks.WEB.getDefaultState(), 3);
		world.setBlockState(new BlockPos(x + 12, y + 6, z + 6), Block1.getDefaultState(), 3);
		world.setBlockState(new BlockPos(x + 0, y + 6, z + 7), Block1.getDefaultState(), 3);
		world.setBlockState(new BlockPos(x + 1, y + 6, z + 7), ModBlocks.red_cable.getDefaultState(), 3);
		world.setBlockState(new BlockPos(x + 2, y + 6, z + 7), Blocks.AIR.getDefaultState(), 3);
		world.setBlockState(new BlockPos(x + 3, y + 6, z + 7), Blocks.AIR.getDefaultState(), 3);
		world.setBlockState(new BlockPos(x + 4, y + 6, z + 7), Blocks.AIR.getDefaultState(), 3);
		world.setBlockState(new BlockPos(x + 5, y + 6, z + 7), Blocks.AIR.getDefaultState(), 3);
		world.setBlockState(new BlockPos(x + 6, y + 6, z + 7), Blocks.AIR.getDefaultState(), 3);
		world.setBlockState(new BlockPos(x + 7, y + 6, z + 7), Blocks.AIR.getDefaultState(), 3);
		world.setBlockState(new BlockPos(x + 8, y + 6, z + 7), Blocks.AIR.getDefaultState(), 3);
		world.setBlockState(new BlockPos(x + 9, y + 6, z + 7), Blocks.AIR.getDefaultState(), 3);
		world.setBlockState(new BlockPos(x + 10, y + 6, z + 7), Blocks.AIR.getDefaultState(), 3);
		world.setBlockState(new BlockPos(x + 11, y + 6, z + 7), Blocks.AIR.getDefaultState(), 3);
		world.setBlockState(new BlockPos(x + 12, y + 6, z + 7), Block1.getDefaultState(), 3);
		world.setBlockState(new BlockPos(x + 0, y + 6, z + 8), Block1.getDefaultState(), 3);
		world.setBlockState(new BlockPos(x + 1, y + 6, z + 8), ModBlocks.red_cable.getDefaultState(), 3);
		world.setBlockState(new BlockPos(x + 2, y + 6, z + 8), Blocks.AIR.getDefaultState(), 3);
		world.setBlockState(new BlockPos(x + 3, y + 6, z + 8), Blocks.AIR.getDefaultState(), 3);
		world.setBlockState(new BlockPos(x + 4, y + 6, z + 8), Blocks.AIR.getDefaultState(), 3);
		world.setBlockState(new BlockPos(x + 5, y + 6, z + 8), Blocks.AIR.getDefaultState(), 3);
		world.setBlockState(new BlockPos(x + 6, y + 6, z + 8), Blocks.AIR.getDefaultState(), 3);
		world.setBlockState(new BlockPos(x + 7, y + 6, z + 8), Blocks.AIR.getDefaultState(), 3);
		world.setBlockState(new BlockPos(x + 8, y + 6, z + 8), Blocks.AIR.getDefaultState(), 3);
		world.setBlockState(new BlockPos(x + 9, y + 6, z + 8), Blocks.AIR.getDefaultState(), 3);
		world.setBlockState(new BlockPos(x + 10, y + 6, z + 8), Blocks.AIR.getDefaultState(), 3);
		world.setBlockState(new BlockPos(x + 11, y + 6, z + 8), Blocks.WEB.getDefaultState(), 3);
		world.setBlockState(new BlockPos(x + 12, y + 6, z + 8), Block1.getDefaultState(), 3);
		world.setBlockState(new BlockPos(x + 0, y + 6, z + 9), Block1.getDefaultState(), 3);
		world.setBlockState(new BlockPos(x + 1, y + 6, z + 9), ModBlocks.cable_switch.getDefaultState().withProperty(CableSwitch.STATE, true), 3);
		world.setBlockState(new BlockPos(x + 2, y + 6, z + 9), Blocks.AIR.getDefaultState(), 3);
		world.setBlockState(new BlockPos(x + 3, y + 6, z + 9), Blocks.AIR.getDefaultState(), 3);
		world.setBlockState(new BlockPos(x + 4, y + 6, z + 9), Blocks.AIR.getDefaultState(), 3);
		world.setBlockState(new BlockPos(x + 5, y + 6, z + 9), Blocks.AIR.getDefaultState(), 3);
		world.setBlockState(new BlockPos(x + 6, y + 6, z + 9), Blocks.AIR.getDefaultState(), 3);
		world.setBlockState(new BlockPos(x + 7, y + 6, z + 9), Blocks.AIR.getDefaultState(), 3);
		world.setBlockState(new BlockPos(x + 8, y + 6, z + 9), Blocks.AIR.getDefaultState(), 3);
		world.setBlockState(new BlockPos(x + 9, y + 6, z + 9), Blocks.AIR.getDefaultState(), 3);
		world.setBlockState(new BlockPos(x + 10, y + 6, z + 9), Blocks.AIR.getDefaultState(), 3);
		world.setBlockState(new BlockPos(x + 11, y + 6, z + 9), Blocks.AIR.getDefaultState(), 3);
		world.setBlockState(new BlockPos(x + 12, y + 6, z + 9), Block1.getDefaultState(), 3);
		world.setBlockState(new BlockPos(x + 0, y + 6, z + 10), Block1.getDefaultState(), 3);
		world.setBlockState(new BlockPos(x + 1, y + 6, z + 10), ModBlocks.red_cable.getDefaultState(), 3);
		world.setBlockState(new BlockPos(x + 2, y + 6, z + 10), ModBlocks.red_cable.getDefaultState(), 3);
		world.setBlockState(new BlockPos(x + 3, y + 6, z + 10), Blocks.AIR.getDefaultState(), 3);
		world.setBlockState(new BlockPos(x + 4, y + 6, z + 10), Blocks.AIR.getDefaultState(), 3);
		world.setBlockState(new BlockPos(x + 5, y + 6, z + 10), Blocks.AIR.getDefaultState(), 3);
		world.setBlockState(new BlockPos(x + 6, y + 6, z + 10), Blocks.AIR.getDefaultState(), 3);
		world.setBlockState(new BlockPos(x + 7, y + 6, z + 10), Blocks.AIR.getDefaultState(), 3);
		world.setBlockState(new BlockPos(x + 8, y + 6, z + 10), Blocks.AIR.getDefaultState(), 3);
		world.setBlockState(new BlockPos(x + 9, y + 6, z + 10), Blocks.AIR.getDefaultState(), 3);
		world.setBlockState(new BlockPos(x + 10, y + 6, z + 10), Blocks.AIR.getDefaultState(), 3);
		world.setBlockState(new BlockPos(x + 11, y + 6, z + 10), Blocks.WEB.getDefaultState(), 3);
		world.setBlockState(new BlockPos(x + 12, y + 6, z + 10), Block1.getDefaultState(), 3);
		world.setBlockState(new BlockPos(x + 0, y + 6, z + 11), Block1.getDefaultState(), 3);
		world.setBlockState(new BlockPos(x + 1, y + 6, z + 11), ModBlocks.red_cable.getDefaultState(), 3);
		world.setBlockState(new BlockPos(x + 2, y + 6, z + 11), Blocks.AIR.getDefaultState(), 3);
		world.setBlockState(new BlockPos(x + 3, y + 6, z + 11), Blocks.AIR.getDefaultState(), 3);
		world.setBlockState(new BlockPos(x + 4, y + 6, z + 11), Blocks.AIR.getDefaultState(), 3);
		world.setBlockState(new BlockPos(x + 5, y + 6, z + 11), Blocks.AIR.getDefaultState(), 3);
		world.setBlockState(new BlockPos(x + 6, y + 6, z + 11), Blocks.AIR.getDefaultState(), 3);
		world.setBlockState(new BlockPos(x + 7, y + 6, z + 11), Blocks.AIR.getDefaultState(), 3);
		world.setBlockState(new BlockPos(x + 8, y + 6, z + 11), Blocks.AIR.getDefaultState(), 3);
		world.setBlockState(new BlockPos(x + 9, y + 6, z + 11), Blocks.AIR.getDefaultState(), 3);
		world.setBlockState(new BlockPos(x + 10, y + 6, z + 11), Blocks.AIR.getDefaultState(), 3);
		world.setBlockState(new BlockPos(x + 11, y + 6, z + 11), Blocks.AIR.getDefaultState(), 3);
		world.setBlockState(new BlockPos(x + 12, y + 6, z + 11), Block1.getDefaultState(), 3);
		world.setBlockState(new BlockPos(x + 0, y + 6, z + 12), Block1.getDefaultState(), 3);
		world.setBlockState(new BlockPos(x + 1, y + 6, z + 12), ModBlocks.red_cable.getDefaultState(), 3);
		world.setBlockState(new BlockPos(x + 2, y + 6, z + 12), ModBlocks.red_cable.getDefaultState(), 3);
		world.setBlockState(new BlockPos(x + 3, y + 6, z + 12), Blocks.AIR.getDefaultState(), 3);
		world.setBlockState(new BlockPos(x + 4, y + 6, z + 12), Blocks.AIR.getDefaultState(), 3);
		world.setBlockState(new BlockPos(x + 5, y + 6, z + 12), Blocks.AIR.getDefaultState(), 3);
		world.setBlockState(new BlockPos(x + 6, y + 6, z + 12), Blocks.AIR.getDefaultState(), 3);
		world.setBlockState(new BlockPos(x + 7, y + 6, z + 12), Blocks.AIR.getDefaultState(), 3);
		world.setBlockState(new BlockPos(x + 8, y + 6, z + 12), Blocks.AIR.getDefaultState(), 3);
		world.setBlockState(new BlockPos(x + 9, y + 6, z + 12), Blocks.AIR.getDefaultState(), 3);
		world.setBlockState(new BlockPos(x + 11, y + 6, z + 12), Block1.getDefaultState(), 3);
		world.setBlockState(new BlockPos(x + 12, y + 6, z + 12), Block1.getDefaultState(), 3);
		world.setBlockState(new BlockPos(x + 0, y + 6, z + 13), Block1.getDefaultState(), 3);
		world.setBlockState(new BlockPos(x + 1, y + 6, z + 13), Blocks.WEB.getDefaultState(), 3);
		world.setBlockState(new BlockPos(x + 2, y + 6, z + 13), Blocks.WEB.getDefaultState(), 3);
		world.setBlockState(new BlockPos(x + 3, y + 6, z + 13), Blocks.AIR.getDefaultState(), 3);
		world.setBlockState(new BlockPos(x + 4, y + 6, z + 13), Blocks.AIR.getDefaultState(), 3);
		world.setBlockState(new BlockPos(x + 5, y + 6, z + 13), Blocks.AIR.getDefaultState(), 3);
		world.setBlockState(new BlockPos(x + 6, y + 6, z + 13), Blocks.AIR.getDefaultState(), 3);
		world.setBlockState(new BlockPos(x + 7, y + 6, z + 13), Blocks.AIR.getDefaultState(), 3);
		world.setBlockState(new BlockPos(x + 8, y + 6, z + 13), Blocks.AIR.getDefaultState(), 3);
		world.setBlockState(new BlockPos(x + 9, y + 6, z + 13), Blocks.AIR.getDefaultState(), 3);
		world.setBlockState(new BlockPos(x + 10, y + 6, z + 13), Block1.getDefaultState(), 3);
		world.setBlockState(new BlockPos(x + 11, y + 6, z + 13), Block1.getDefaultState(), 3);
		world.setBlockState(new BlockPos(x + 12, y + 6, z + 13), Block1.getDefaultState(), 3);
		world.setBlockState(new BlockPos(x + 1, y + 6, z + 14), Block1.getDefaultState(), 3);
		world.setBlockState(new BlockPos(x + 2, y + 6, z + 14), Block1.getDefaultState(), 3);
		world.setBlockState(new BlockPos(x + 3, y + 6, z + 14), Block1.getDefaultState(), 3);
		world.setBlockState(new BlockPos(x + 4, y + 6, z + 14), Block1.getDefaultState(), 3);
		world.setBlockState(new BlockPos(x + 5, y + 6, z + 14), Block1.getDefaultState(), 3);
		world.setBlockState(new BlockPos(x + 6, y + 6, z + 14), Block1.getDefaultState(), 3);
		world.setBlockState(new BlockPos(x + 7, y + 6, z + 14), Block1.getDefaultState(), 3);
		world.setBlockState(new BlockPos(x + 8, y + 6, z + 14), Block1.getDefaultState(), 3);
		world.setBlockState(new BlockPos(x + 9, y + 6, z + 14), Block1.getDefaultState(), 3);
		world.setBlockState(new BlockPos(x + 10, y + 6, z + 14), Block1.getDefaultState(), 3);
		world.setBlockState(new BlockPos(x + 11, y + 6, z + 14), Block1.getDefaultState(), 3);
		world.setBlockState(new BlockPos(x + 0, y + 7, z + 4), Block1.getDefaultState(), 3);
		world.setBlockState(new BlockPos(x + 1, y + 7, z + 4), Block1.getDefaultState(), 3);
		world.setBlockState(new BlockPos(x + 2, y + 7, z + 4), Block1.getDefaultState(), 3);
		world.setBlockState(new BlockPos(x + 3, y + 7, z + 4), Block1.getDefaultState(), 3);
		world.setBlockState(new BlockPos(x + 4, y + 7, z + 4), Block1.getDefaultState(), 3);
		world.setBlockState(new BlockPos(x + 5, y + 7, z + 4), Block1.getDefaultState(), 3);
		world.setBlockState(new BlockPos(x + 6, y + 7, z + 4), Block1.getDefaultState(), 3);
		world.setBlockState(new BlockPos(x + 7, y + 7, z + 4), Block1.getDefaultState(), 3);
		world.setBlockState(new BlockPos(x + 8, y + 7, z + 4), Block1.getDefaultState(), 3);
		world.setBlockState(new BlockPos(x + 9, y + 7, z + 4), Block1.getDefaultState(), 3);
		world.setBlockState(new BlockPos(x + 10, y + 7, z + 4), Block1.getDefaultState(), 3);
		world.setBlockState(new BlockPos(x + 11, y + 7, z + 4), Block1.getDefaultState(), 3);
		world.setBlockState(new BlockPos(x + 0, y + 7, z + 5), Block1.getDefaultState(), 3);
		world.setBlockState(new BlockPos(x + 1, y + 7, z + 5), Block1.getDefaultState(), 3);
		world.setBlockState(new BlockPos(x + 2, y + 7, z + 5), Block1.getDefaultState(), 3);
		world.setBlockState(new BlockPos(x + 3, y + 7, z + 5), Block1.getDefaultState(), 3);
		world.setBlockState(new BlockPos(x + 4, y + 7, z + 5), Block1.getDefaultState(), 3);
		world.setBlockState(new BlockPos(x + 5, y + 7, z + 5), Block1.getDefaultState(), 3);
		world.setBlockState(new BlockPos(x + 6, y + 7, z + 5), Block1.getDefaultState(), 3);
		world.setBlockState(new BlockPos(x + 7, y + 7, z + 5), Block1.getDefaultState(), 3);
		world.setBlockState(new BlockPos(x + 8, y + 7, z + 5), Block1.getDefaultState(), 3);
		world.setBlockState(new BlockPos(x + 9, y + 7, z + 5), Block1.getDefaultState(), 3);
		world.setBlockState(new BlockPos(x + 10, y + 7, z + 5), Block1.getDefaultState(), 3);
		world.setBlockState(new BlockPos(x + 11, y + 7, z + 5), Block1.getDefaultState(), 3);
		world.setBlockState(new BlockPos(x + 0, y + 7, z + 6), Block1.getDefaultState(), 3);
		world.setBlockState(new BlockPos(x + 1, y + 7, z + 6), Block1.getDefaultState(), 3);
		world.setBlockState(new BlockPos(x + 2, y + 7, z + 6), Block1.getDefaultState(), 3);
		world.setBlockState(new BlockPos(x + 3, y + 7, z + 6), Block1.getDefaultState(), 3);
		world.setBlockState(new BlockPos(x + 4, y + 7, z + 6), Block1.getDefaultState(), 3);
		world.setBlockState(new BlockPos(x + 5, y + 7, z + 6), Block1.getDefaultState(), 3);
		world.setBlockState(new BlockPos(x + 6, y + 7, z + 6), Block1.getDefaultState(), 3);
		world.setBlockState(new BlockPos(x + 7, y + 7, z + 6), Block1.getDefaultState(), 3);
		world.setBlockState(new BlockPos(x + 8, y + 7, z + 6), Block1.getDefaultState(), 3);
		world.setBlockState(new BlockPos(x + 9, y + 7, z + 6), Block1.getDefaultState(), 3);
		world.setBlockState(new BlockPos(x + 10, y + 7, z + 6), Block1.getDefaultState(), 3);
		world.setBlockState(new BlockPos(x + 11, y + 7, z + 6), Block1.getDefaultState(), 3);
		world.setBlockState(new BlockPos(x + 0, y + 7, z + 7), Block1.getDefaultState(), 3);
		world.setBlockState(new BlockPos(x + 1, y + 7, z + 7), Block1.getDefaultState(), 3);
		world.setBlockState(new BlockPos(x + 2, y + 7, z + 7), Block1.getDefaultState(), 3);
		world.setBlockState(new BlockPos(x + 3, y + 7, z + 7), Block1.getDefaultState(), 3);
		world.setBlockState(new BlockPos(x + 4, y + 7, z + 7), Block1.getDefaultState(), 3);
		world.setBlockState(new BlockPos(x + 5, y + 7, z + 7), Block1.getDefaultState(), 3);
		world.setBlockState(new BlockPos(x + 6, y + 7, z + 7), Block1.getDefaultState(), 3);
		world.setBlockState(new BlockPos(x + 7, y + 7, z + 7), Block1.getDefaultState(), 3);
		world.setBlockState(new BlockPos(x + 8, y + 7, z + 7), Blocks.AIR.getDefaultState(), 3);
		world.setBlockState(new BlockPos(x + 9, y + 7, z + 7), Block1.getDefaultState(), 3);
		world.setBlockState(new BlockPos(x + 10, y + 7, z + 7), Block1.getDefaultState(), 3);
		world.setBlockState(new BlockPos(x + 11, y + 7, z + 7), Block1.getDefaultState(), 3);
		world.setBlockState(new BlockPos(x + 0, y + 7, z + 8), Block1.getDefaultState(), 3);
		world.setBlockState(new BlockPos(x + 1, y + 7, z + 8), Block1.getDefaultState(), 3);
		world.setBlockState(new BlockPos(x + 2, y + 7, z + 8), Block1.getDefaultState(), 3);
		world.setBlockState(new BlockPos(x + 3, y + 7, z + 8), Block1.getDefaultState(), 3);
		world.setBlockState(new BlockPos(x + 4, y + 7, z + 8), Block1.getDefaultState(), 3);
		world.setBlockState(new BlockPos(x + 5, y + 7, z + 8), Block1.getDefaultState(), 3);
		world.setBlockState(new BlockPos(x + 6, y + 7, z + 8), Block1.getDefaultState(), 3);
		world.setBlockState(new BlockPos(x + 7, y + 7, z + 8), Blocks.AIR.getDefaultState(), 3);
		world.setBlockState(new BlockPos(x + 8, y + 7, z + 8), Blocks.AIR.getDefaultState(), 3);
		world.setBlockState(new BlockPos(x + 9, y + 7, z + 8), Block1.getDefaultState(), 3);
		world.setBlockState(new BlockPos(x + 10, y + 7, z + 8), Block1.getDefaultState(), 3);
		world.setBlockState(new BlockPos(x + 11, y + 7, z + 8), Block1.getDefaultState(), 3);
		world.setBlockState(new BlockPos(x + 0, y + 7, z + 9), Block1.getDefaultState(), 3);
		world.setBlockState(new BlockPos(x + 1, y + 7, z + 9), Block1.getDefaultState(), 3);
		world.setBlockState(new BlockPos(x + 2, y + 7, z + 9), Block1.getDefaultState(), 3);
		world.setBlockState(new BlockPos(x + 3, y + 7, z + 9), Block1.getDefaultState(), 3);
		world.setBlockState(new BlockPos(x + 4, y + 7, z + 9), Block1.getDefaultState(), 3);
		world.setBlockState(new BlockPos(x + 5, y + 7, z + 9), Block1.getDefaultState(), 3);
		world.setBlockState(new BlockPos(x + 6, y + 7, z + 9), Blocks.AIR.getDefaultState(), 3);
		world.setBlockState(new BlockPos(x + 7, y + 7, z + 9), Blocks.AIR.getDefaultState(), 3);
		world.setBlockState(new BlockPos(x + 8, y + 7, z + 9), Blocks.AIR.getDefaultState(), 3);
		world.setBlockState(new BlockPos(x + 9, y + 7, z + 9), Blocks.AIR.getDefaultState(), 3);
		world.setBlockState(new BlockPos(x + 10, y + 7, z + 9), Block1.getDefaultState(), 3);
		world.setBlockState(new BlockPos(x + 11, y + 7, z + 9), Block1.getDefaultState(), 3);
		world.setBlockState(new BlockPos(x + 0, y + 7, z + 10), Block1.getDefaultState(), 3);
		world.setBlockState(new BlockPos(x + 1, y + 7, z + 10), Block1.getDefaultState(), 3);
		world.setBlockState(new BlockPos(x + 2, y + 7, z + 10), ModBlocks.red_cable.getDefaultState(), 3);
		world.setBlockState(new BlockPos(x + 3, y + 7, z + 10), Block1.getDefaultState(), 3);
		world.setBlockState(new BlockPos(x + 4, y + 7, z + 10), Block1.getDefaultState(), 3);
		world.setBlockState(new BlockPos(x + 5, y + 7, z + 10), Blocks.AIR.getDefaultState(), 3);
		world.setBlockState(new BlockPos(x + 6, y + 7, z + 10), Blocks.AIR.getDefaultState(), 3);
		world.setBlockState(new BlockPos(x + 7, y + 7, z + 10), Blocks.AIR.getDefaultState(), 3);
		world.setBlockState(new BlockPos(x + 8, y + 7, z + 10), Blocks.AIR.getDefaultState(), 3);
		world.setBlockState(new BlockPos(x + 9, y + 7, z + 10), Blocks.AIR.getDefaultState(), 3);
		world.setBlockState(new BlockPos(x + 10, y + 7, z + 10), Block1.getDefaultState(), 3);
		world.setBlockState(new BlockPos(x + 11, y + 7, z + 10), Block1.getDefaultState(), 3);
		world.setBlockState(new BlockPos(x + 0, y + 7, z + 11), Block1.getDefaultState(), 3);
		world.setBlockState(new BlockPos(x + 1, y + 7, z + 11), Block1.getDefaultState(), 3);
		world.setBlockState(new BlockPos(x + 2, y + 7, z + 11), Block1.getDefaultState(), 3);
		world.setBlockState(new BlockPos(x + 3, y + 7, z + 11), Block1.getDefaultState(), 3);
		world.setBlockState(new BlockPos(x + 4, y + 7, z + 11), Blocks.AIR.getDefaultState(), 3);
		world.setBlockState(new BlockPos(x + 5, y + 7, z + 11), Blocks.AIR.getDefaultState(), 3);
		world.setBlockState(new BlockPos(x + 6, y + 7, z + 11), Blocks.AIR.getDefaultState(), 3);
		world.setBlockState(new BlockPos(x + 7, y + 7, z + 11), Blocks.AIR.getDefaultState(), 3);
		world.setBlockState(new BlockPos(x + 8, y + 7, z + 11), Blocks.AIR.getDefaultState(), 3);
		world.setBlockState(new BlockPos(x + 9, y + 7, z + 11), Block1.getDefaultState(), 3);
		world.setBlockState(new BlockPos(x + 10, y + 7, z + 11), Block1.getDefaultState(), 3);
		world.setBlockState(new BlockPos(x + 11, y + 7, z + 11), Block1.getDefaultState(), 3);
		world.setBlockState(new BlockPos(x + 0, y + 7, z + 12), Block1.getDefaultState(), 3);
		world.setBlockState(new BlockPos(x + 1, y + 7, z + 12), Block1.getDefaultState(), 3);
		world.setBlockState(new BlockPos(x + 2, y + 7, z + 12), ModBlocks.red_cable.getDefaultState(), 3);
		world.setBlockState(new BlockPos(x + 3, y + 7, z + 12), Block1.getDefaultState(), 3);
		world.setBlockState(new BlockPos(x + 4, y + 7, z + 12), Block1.getDefaultState(), 3);
		world.setBlockState(new BlockPos(x + 5, y + 7, z + 12), Blocks.AIR.getDefaultState(), 3);
		world.setBlockState(new BlockPos(x + 6, y + 7, z + 12), Block1.getDefaultState(), 3);
		world.setBlockState(new BlockPos(x + 7, y + 7, z + 12), Blocks.AIR.getDefaultState(), 3);
		world.setBlockState(new BlockPos(x + 8, y + 7, z + 12), Block1.getDefaultState(), 3);
		world.setBlockState(new BlockPos(x + 9, y + 7, z + 12), Block1.getDefaultState(), 3);
		world.setBlockState(new BlockPos(x + 11, y + 7, z + 12), Block1.getDefaultState(), 3);
		world.setBlockState(new BlockPos(x + 0, y + 7, z + 13), Block1.getDefaultState(), 3);
		world.setBlockState(new BlockPos(x + 1, y + 7, z + 13), Block1.getDefaultState(), 3);
		world.setBlockState(new BlockPos(x + 2, y + 7, z + 13), Block1.getDefaultState(), 3);
		world.setBlockState(new BlockPos(x + 3, y + 7, z + 13), Block1.getDefaultState(), 3);
		world.setBlockState(new BlockPos(x + 4, y + 7, z + 13), Block1.getDefaultState(), 3);
		world.setBlockState(new BlockPos(x + 5, y + 7, z + 13), Block1.getDefaultState(), 3);
		world.setBlockState(new BlockPos(x + 6, y + 7, z + 13), Block1.getDefaultState(), 3);
		world.setBlockState(new BlockPos(x + 7, y + 7, z + 13), Block1.getDefaultState(), 3);
		world.setBlockState(new BlockPos(x + 8, y + 7, z + 13), Block1.getDefaultState(), 3);
		world.setBlockState(new BlockPos(x + 9, y + 7, z + 13), Block1.getDefaultState(), 3);
		world.setBlockState(new BlockPos(x + 10, y + 7, z + 13), Block1.getDefaultState(), 3);
		world.setBlockState(new BlockPos(x + 11, y + 7, z + 13), Block1.getDefaultState(), 3);
		world.setBlockState(new BlockPos(x + 1, y + 7, z + 14), Block1.getDefaultState(), 3);
		world.setBlockState(new BlockPos(x + 2, y + 7, z + 14), Block1.getDefaultState(), 3);
		world.setBlockState(new BlockPos(x + 3, y + 7, z + 14), Block1.getDefaultState(), 3);
		world.setBlockState(new BlockPos(x + 4, y + 7, z + 14), Block1.getDefaultState(), 3);
		world.setBlockState(new BlockPos(x + 5, y + 7, z + 14), Block1.getDefaultState(), 3);
		world.setBlockState(new BlockPos(x + 6, y + 7, z + 14), Block1.getDefaultState(), 3);
		world.setBlockState(new BlockPos(x + 7, y + 7, z + 14), Block1.getDefaultState(), 3);
		world.setBlockState(new BlockPos(x + 8, y + 7, z + 14), Block1.getDefaultState(), 3);
		world.setBlockState(new BlockPos(x + 9, y + 7, z + 14), Block1.getDefaultState(), 3);
		world.setBlockState(new BlockPos(x + 10, y + 7, z + 14), Block1.getDefaultState(), 3);
		world.setBlockState(new BlockPos(x + 11, y + 7, z + 14), Block1.getDefaultState(), 3);
		world.setBlockState(new BlockPos(x + 0, y + 8, z + 1), Blocks.STONE_STAIRS.getDefaultState().withProperty(BlockStairs.HALF, BlockStairs.EnumHalf.BOTTOM).withProperty(BlockStairs.FACING, EnumFacing.SOUTH), 3);
		world.setBlockState(new BlockPos(x + 1, y + 8, z + 1), Blocks.STONE_STAIRS.getDefaultState().withProperty(BlockStairs.HALF, BlockStairs.EnumHalf.BOTTOM).withProperty(BlockStairs.FACING, EnumFacing.SOUTH), 3);
		world.setBlockState(new BlockPos(x + 2, y + 8, z + 1), Blocks.STONE_STAIRS.getDefaultState().withProperty(BlockStairs.HALF, BlockStairs.EnumHalf.BOTTOM).withProperty(BlockStairs.FACING, EnumFacing.SOUTH), 3);
		world.setBlockState(new BlockPos(x + 3, y + 8, z + 1), Blocks.STONE_STAIRS.getDefaultState().withProperty(BlockStairs.HALF, BlockStairs.EnumHalf.BOTTOM).withProperty(BlockStairs.FACING, EnumFacing.SOUTH), 3);
		world.setBlockState(new BlockPos(x + 4, y + 8, z + 1), Blocks.STONE_STAIRS.getDefaultState().withProperty(BlockStairs.HALF, BlockStairs.EnumHalf.BOTTOM).withProperty(BlockStairs.FACING, EnumFacing.SOUTH), 3);
		world.setBlockState(new BlockPos(x + 5, y + 8, z + 1), Blocks.STONE_STAIRS.getDefaultState().withProperty(BlockStairs.HALF, BlockStairs.EnumHalf.BOTTOM).withProperty(BlockStairs.FACING, EnumFacing.SOUTH), 3);
		world.setBlockState(new BlockPos(x + 6, y + 8, z + 1), Blocks.STONE_STAIRS.getDefaultState().withProperty(BlockStairs.HALF, BlockStairs.EnumHalf.BOTTOM).withProperty(BlockStairs.FACING, EnumFacing.SOUTH), 3);
		world.setBlockState(new BlockPos(x + 7, y + 8, z + 1), Blocks.STONE_STAIRS.getDefaultState().withProperty(BlockStairs.HALF, BlockStairs.EnumHalf.BOTTOM).withProperty(BlockStairs.FACING, EnumFacing.SOUTH), 3);
		world.setBlockState(new BlockPos(x + 8, y + 8, z + 1), Blocks.STONE_STAIRS.getDefaultState().withProperty(BlockStairs.HALF, BlockStairs.EnumHalf.BOTTOM).withProperty(BlockStairs.FACING, EnumFacing.SOUTH), 3);
		world.setBlockState(new BlockPos(x + 9, y + 8, z + 1), Blocks.STONE_STAIRS.getDefaultState().withProperty(BlockStairs.HALF, BlockStairs.EnumHalf.BOTTOM).withProperty(BlockStairs.FACING, EnumFacing.SOUTH), 3);
		world.setBlockState(new BlockPos(x + 10, y + 8, z + 1), Blocks.STONE_STAIRS.getDefaultState().withProperty(BlockStairs.HALF, BlockStairs.EnumHalf.BOTTOM).withProperty(BlockStairs.FACING, EnumFacing.SOUTH), 3);
		world.setBlockState(new BlockPos(x + 11, y + 8, z + 1), Blocks.STONE_STAIRS.getDefaultState().withProperty(BlockStairs.HALF, BlockStairs.EnumHalf.BOTTOM).withProperty(BlockStairs.FACING, EnumFacing.SOUTH), 3);
		world.setBlockState(new BlockPos(x + 0, y + 8, z + 2), Blocks.STONE_STAIRS.getDefaultState().withProperty(BlockStairs.HALF, BlockStairs.EnumHalf.BOTTOM).withProperty(BlockStairs.FACING, EnumFacing.EAST), 3);
		world.setBlockState(new BlockPos(x + 1, y + 8, z + 2), Blocks.COBBLESTONE.getDefaultState(), 3);
		world.setBlockState(new BlockPos(x + 2, y + 8, z + 2), Blocks.COBBLESTONE.getDefaultState(), 3);
		world.setBlockState(new BlockPos(x + 3, y + 8, z + 2), Blocks.MOSSY_COBBLESTONE.getDefaultState(), 3);
		world.setBlockState(new BlockPos(x + 4, y + 8, z + 2), Blocks.COBBLESTONE.getDefaultState(), 3);
		world.setBlockState(new BlockPos(x + 5, y + 8, z + 2), Blocks.COBBLESTONE.getDefaultState(), 3);
		world.setBlockState(new BlockPos(x + 6, y + 8, z + 2), Blocks.COBBLESTONE.getDefaultState(), 3);
		world.setBlockState(new BlockPos(x + 7, y + 8, z + 2), Blocks.COBBLESTONE.getDefaultState(), 3);
		world.setBlockState(new BlockPos(x + 8, y + 8, z + 2), Blocks.COBBLESTONE.getDefaultState(), 3);
		world.setBlockState(new BlockPos(x + 9, y + 8, z + 2), Blocks.COBBLESTONE.getDefaultState(), 3);
		world.setBlockState(new BlockPos(x + 10, y + 8, z + 2), Blocks.COBBLESTONE.getDefaultState(), 3);
		world.setBlockState(new BlockPos(x + 11, y + 8, z + 2), Blocks.COBBLESTONE.getDefaultState(), 3);
		world.setBlockState(new BlockPos(x + 0, y + 8, z + 3), Blocks.STONE_STAIRS.getDefaultState().withProperty(BlockStairs.HALF, BlockStairs.EnumHalf.BOTTOM).withProperty(BlockStairs.FACING, EnumFacing.EAST), 3);
		world.setBlockState(new BlockPos(x + 1, y + 8, z + 3), Blocks.MOSSY_COBBLESTONE.getDefaultState(), 3);
		world.setBlockState(new BlockPos(x + 2, y + 8, z + 3), Blocks.COBBLESTONE.getDefaultState(), 3);
		world.setBlockState(new BlockPos(x + 3, y + 8, z + 3), Blocks.MOSSY_COBBLESTONE.getDefaultState(), 3);
		world.setBlockState(new BlockPos(x + 4, y + 8, z + 3), Blocks.MOSSY_COBBLESTONE.getDefaultState(), 3);
		world.setBlockState(new BlockPos(x + 5, y + 8, z + 3), Blocks.COBBLESTONE.getDefaultState(), 3);
		world.setBlockState(new BlockPos(x + 6, y + 8, z + 3), Blocks.STONE_SLAB.getDefaultState().withProperty(BlockStoneSlab.HALF, BlockSlab.EnumBlockHalf.BOTTOM).withProperty(BlockStoneSlab.VARIANT, BlockStoneSlab.EnumType.byMetadata(3)), 3);
		world.setBlockState(new BlockPos(x + 7, y + 8, z + 3), Blocks.MOSSY_COBBLESTONE.getDefaultState(), 3);
		world.setBlockState(new BlockPos(x + 8, y + 8, z + 3), Blocks.STONE_STAIRS.getDefaultState().withProperty(BlockStairs.HALF, BlockStairs.EnumHalf.BOTTOM).withProperty(BlockStairs.FACING, EnumFacing.WEST), 3);
		world.setBlockState(new BlockPos(x + 9, y + 8, z + 3), Blocks.COBBLESTONE.getDefaultState(), 3);
		world.setBlockState(new BlockPos(x + 10, y + 8, z + 3), Blocks.STONE_STAIRS.getDefaultState().withProperty(BlockStairs.HALF, BlockStairs.EnumHalf.BOTTOM).withProperty(BlockStairs.FACING, EnumFacing.NORTH), 3);
		world.setBlockState(new BlockPos(x + 11, y + 8, z + 3), Blocks.COBBLESTONE.getDefaultState(), 3);
		world.setBlockState(new BlockPos(x + 0, y + 8, z + 4), Blocks.STONE_STAIRS.getDefaultState().withProperty(BlockStairs.HALF, BlockStairs.EnumHalf.BOTTOM).withProperty(BlockStairs.FACING, EnumFacing.EAST), 3);
		world.setBlockState(new BlockPos(x + 1, y + 8, z + 4), Blocks.COBBLESTONE.getDefaultState(), 3);
		world.setBlockState(new BlockPos(x + 2, y + 8, z + 4), Blocks.COBBLESTONE.getDefaultState(), 3);
		world.setBlockState(new BlockPos(x + 3, y + 8, z + 4), Blocks.COBBLESTONE.getDefaultState(), 3);
		world.setBlockState(new BlockPos(x + 4, y + 8, z + 4), Blocks.COBBLESTONE.getDefaultState(), 3);
		world.setBlockState(new BlockPos(x + 5, y + 8, z + 4), Blocks.COBBLESTONE.getDefaultState(), 3);
		world.setBlockState(new BlockPos(x + 6, y + 8, z + 4), Blocks.COBBLESTONE.getDefaultState(), 3);
		world.setBlockState(new BlockPos(x + 7, y + 8, z + 4), Blocks.COBBLESTONE.getDefaultState(), 3);
		world.setBlockState(new BlockPos(x + 8, y + 8, z + 4), Blocks.COBBLESTONE.getDefaultState(), 3);
		world.setBlockState(new BlockPos(x + 9, y + 8, z + 4), Blocks.COBBLESTONE.getDefaultState(), 3);
		world.setBlockState(new BlockPos(x + 10, y + 8, z + 4), Blocks.COBBLESTONE.getDefaultState(), 3);
		world.setBlockState(new BlockPos(x + 11, y + 8, z + 4), Blocks.COBBLESTONE.getDefaultState(), 3);
		world.setBlockState(new BlockPos(x + 0, y + 8, z + 5), Blocks.DIRT.getDefaultState(), 3);
		world.setBlockState(new BlockPos(x + 1, y + 8, z + 5), Blocks.COBBLESTONE.getDefaultState(), 3);
		world.setBlockState(new BlockPos(x + 2, y + 8, z + 5), Blocks.COBBLESTONE.getDefaultState(), 3);
		world.setBlockState(new BlockPos(x + 3, y + 8, z + 5), Blocks.COBBLESTONE.getDefaultState(), 3);
		world.setBlockState(new BlockPos(x + 4, y + 8, z + 5), Blocks.COBBLESTONE.getDefaultState(), 3);
		world.setBlockState(new BlockPos(x + 5, y + 8, z + 5), Blocks.COBBLESTONE.getDefaultState(), 3);
		world.setBlockState(new BlockPos(x + 6, y + 8, z + 5), Blocks.COBBLESTONE.getDefaultState(), 3);
		world.setBlockState(new BlockPos(x + 7, y + 8, z + 5), Blocks.COBBLESTONE.getDefaultState(), 3);
		world.setBlockState(new BlockPos(x + 8, y + 8, z + 5), Blocks.COBBLESTONE.getDefaultState(), 3);
		world.setBlockState(new BlockPos(x + 9, y + 8, z + 5), Blocks.COBBLESTONE.getDefaultState(), 3);
		world.setBlockState(new BlockPos(x + 10, y + 8, z + 5), Blocks.COBBLESTONE.getDefaultState(), 3);
		world.setBlockState(new BlockPos(x + 11, y + 8, z + 5), Blocks.COBBLESTONE.getDefaultState(), 3);
		world.setBlockState(new BlockPos(x + 0, y + 8, z + 6), Blocks.DIRT.getDefaultState(), 3);
		world.setBlockState(new BlockPos(x + 1, y + 8, z + 6), Blocks.COBBLESTONE.getDefaultState(), 3);
		world.setBlockState(new BlockPos(x + 2, y + 8, z + 6), Blocks.STAINED_HARDENED_CLAY.getDefaultState().withProperty(BlockStainedHardenedClay.COLOR, EnumDyeColor.byMetadata(15)), 3);
		world.setBlockState(new BlockPos(x + 3, y + 8, z + 6), Blocks.STAINED_HARDENED_CLAY.getDefaultState().withProperty(BlockStainedHardenedClay.COLOR, EnumDyeColor.byMetadata(0)), 3);
		world.setBlockState(new BlockPos(x + 4, y + 8, z + 6), Blocks.STAINED_HARDENED_CLAY.getDefaultState().withProperty(BlockStainedHardenedClay.COLOR, EnumDyeColor.byMetadata(15)), 3);
		world.setBlockState(new BlockPos(x + 5, y + 8, z + 6), Blocks.PLANKS.getDefaultState().withProperty(BlockPlanks.VARIANT, BlockPlanks.EnumType.SPRUCE), 3);
		world.setBlockState(new BlockPos(x + 6, y + 8, z + 6), Blocks.SPRUCE_STAIRS.getDefaultState().withProperty(BlockStairs.HALF, BlockStairs.EnumHalf.BOTTOM).withProperty(BlockStairs.FACING, EnumFacing.WEST), 3);
		world.setBlockState(new BlockPos(x + 7, y + 8, z + 6), Blocks.PLANKS.getDefaultState().withProperty(BlockPlanks.VARIANT, BlockPlanks.EnumType.SPRUCE), 3);
		world.setBlockState(new BlockPos(x + 8, y + 8, z + 6), Blocks.PLANKS.getDefaultState().withProperty(BlockPlanks.VARIANT, BlockPlanks.EnumType.SPRUCE), 3);
		world.setBlockState(new BlockPos(x + 9, y + 8, z + 6), Blocks.SPRUCE_STAIRS.getDefaultState().withProperty(BlockStairs.HALF, BlockStairs.EnumHalf.BOTTOM).withProperty(BlockStairs.FACING, EnumFacing.NORTH), 3);
		world.setBlockState(new BlockPos(x + 10, y + 8, z + 6), Blocks.SPRUCE_STAIRS.getDefaultState().withProperty(BlockStairs.HALF, BlockStairs.EnumHalf.BOTTOM).withProperty(BlockStairs.FACING, EnumFacing.NORTH), 3);
		world.setBlockState(new BlockPos(x + 11, y + 8, z + 6), Blocks.COBBLESTONE.getDefaultState(), 3);
		world.setBlockState(new BlockPos(x + 0, y + 8, z + 7), Blocks.DIRT.getDefaultState(), 3);
		world.setBlockState(new BlockPos(x + 1, y + 8, z + 7), Blocks.COBBLESTONE.getDefaultState(), 3);
		world.setBlockState(new BlockPos(x + 2, y + 8, z + 7), Blocks.STAINED_HARDENED_CLAY.getDefaultState().withProperty(BlockStainedHardenedClay.COLOR, EnumDyeColor.byMetadata(0)), 3);
		world.setBlockState(new BlockPos(x + 3, y + 8, z + 7), Blocks.STAINED_HARDENED_CLAY.getDefaultState().withProperty(BlockStainedHardenedClay.COLOR, EnumDyeColor.byMetadata(15)), 3);
		world.setBlockState(new BlockPos(x + 4, y + 8, z + 7), Blocks.STAINED_HARDENED_CLAY.getDefaultState().withProperty(BlockStainedHardenedClay.COLOR, EnumDyeColor.byMetadata(0)), 3);
		world.setBlockState(new BlockPos(x + 5, y + 8, z + 7), Blocks.PLANKS.getDefaultState().withProperty(BlockPlanks.VARIANT, BlockPlanks.EnumType.SPRUCE), 3);
		world.setBlockState(new BlockPos(x + 6, y + 8, z + 7), Blocks.SPRUCE_STAIRS.getDefaultState().withProperty(BlockStairs.HALF, BlockStairs.EnumHalf.BOTTOM).withProperty(BlockStairs.FACING, EnumFacing.WEST), 3);
		world.setBlockState(new BlockPos(x + 7, y + 8, z + 7), Blocks.AIR.getDefaultState(), 3);
		world.setBlockState(new BlockPos(x + 8, y + 8, z + 7), Blocks.AIR.getDefaultState(), 3);
		world.setBlockState(new BlockPos(x + 9, y + 8, z + 7), Blocks.SPRUCE_STAIRS.getDefaultState().withProperty(BlockStairs.HALF, BlockStairs.EnumHalf.BOTTOM).withProperty(BlockStairs.FACING, EnumFacing.EAST), 3);
		world.setBlockState(new BlockPos(x + 10, y + 8, z + 7), Blocks.SPRUCE_STAIRS.getDefaultState().withProperty(BlockStairs.HALF, BlockStairs.EnumHalf.BOTTOM).withProperty(BlockStairs.FACING, EnumFacing.EAST), 3);
		world.setBlockState(new BlockPos(x + 11, y + 8, z + 7), Blocks.SPRUCE_STAIRS.getDefaultState().withProperty(BlockStairs.HALF, BlockStairs.EnumHalf.TOP).withProperty(BlockStairs.FACING, EnumFacing.EAST), 3);
		world.setBlockState(new BlockPos(x + 0, y + 8, z + 8), Blocks.DIRT.getDefaultState(), 3);
		world.setBlockState(new BlockPos(x + 1, y + 8, z + 8), Blocks.COBBLESTONE.getDefaultState(), 3);
		world.setBlockState(new BlockPos(x + 2, y + 8, z + 8), Blocks.STAINED_HARDENED_CLAY.getDefaultState().withProperty(BlockStainedHardenedClay.COLOR, EnumDyeColor.byMetadata(15)), 3);
		world.setBlockState(new BlockPos(x + 3, y + 8, z + 8), Blocks.STAINED_HARDENED_CLAY.getDefaultState().withProperty(BlockStainedHardenedClay.COLOR, EnumDyeColor.byMetadata(0)), 3);
		world.setBlockState(new BlockPos(x + 4, y + 8, z + 8), Blocks.STAINED_HARDENED_CLAY.getDefaultState().withProperty(BlockStainedHardenedClay.COLOR, EnumDyeColor.byMetadata(15)), 3);
		world.setBlockState(new BlockPos(x + 5, y + 8, z + 8), Blocks.PLANKS.getDefaultState().withProperty(BlockPlanks.VARIANT, BlockPlanks.EnumType.SPRUCE), 3);
		world.setBlockState(new BlockPos(x + 6, y + 8, z + 8), Blocks.PLANKS.getDefaultState().withProperty(BlockPlanks.VARIANT, BlockPlanks.EnumType.SPRUCE), 3);
		world.setBlockState(new BlockPos(x + 7, y + 8, z + 8), Blocks.AIR.getDefaultState(), 3);
		world.setBlockState(new BlockPos(x + 8, y + 8, z + 8), Blocks.AIR.getDefaultState(), 3);
		world.setBlockState(new BlockPos(x + 9, y + 8, z + 8), Blocks.PLANKS.getDefaultState().withProperty(BlockPlanks.VARIANT, BlockPlanks.EnumType.SPRUCE), 3);
		world.setBlockState(new BlockPos(x + 10, y + 8, z + 8), Blocks.WOODEN_SLAB.getDefaultState().withProperty(BlockHalfWoodSlab.HALF, BlockSlab.EnumBlockHalf.BOTTOM).withProperty(BlockHalfWoodSlab.VARIANT, BlockPlanks.EnumType.byMetadata(1)), 3);
		world.setBlockState(new BlockPos(x + 11, y + 8, z + 8), Blocks.COBBLESTONE.getDefaultState(), 3);
		world.setBlockState(new BlockPos(x + 0, y + 8, z + 9), Blocks.GRASS.getDefaultState(), 3);
		world.setBlockState(new BlockPos(x + 1, y + 8, z + 9), Blocks.COBBLESTONE.getDefaultState(), 3);
		world.setBlockState(new BlockPos(x + 2, y + 8, z + 9), Blocks.STAINED_HARDENED_CLAY.getDefaultState().withProperty(BlockStainedHardenedClay.COLOR, EnumDyeColor.byMetadata(0)), 3);
		world.setBlockState(new BlockPos(x + 3, y + 8, z + 9), Blocks.STAINED_HARDENED_CLAY.getDefaultState().withProperty(BlockStainedHardenedClay.COLOR, EnumDyeColor.byMetadata(15)), 3);
		world.setBlockState(new BlockPos(x + 4, y + 8, z + 9), Blocks.STAINED_HARDENED_CLAY.getDefaultState().withProperty(BlockStainedHardenedClay.COLOR, EnumDyeColor.byMetadata(0)), 3);
		world.setBlockState(new BlockPos(x + 5, y + 8, z + 9), Blocks.SPRUCE_STAIRS.getDefaultState().withProperty(BlockStairs.HALF, BlockStairs.EnumHalf.BOTTOM).withProperty(BlockStairs.FACING, EnumFacing.WEST), 3);
		world.setBlockState(new BlockPos(x + 6, y + 8, z + 9), Blocks.AIR.getDefaultState(), 3);
		world.setBlockState(new BlockPos(x + 7, y + 8, z + 9), Blocks.AIR.getDefaultState(), 3);
		world.setBlockState(new BlockPos(x + 8, y + 8, z + 9), Blocks.AIR.getDefaultState(), 3);
		world.setBlockState(new BlockPos(x + 9, y + 8, z + 9), Blocks.PLANKS.getDefaultState().withProperty(BlockPlanks.VARIANT, BlockPlanks.EnumType.SPRUCE), 3);
		world.setBlockState(new BlockPos(x + 10, y + 8, z + 9), Blocks.PLANKS.getDefaultState().withProperty(BlockPlanks.VARIANT, BlockPlanks.EnumType.SPRUCE), 3);
		world.setBlockState(new BlockPos(x + 11, y + 8, z + 9), Blocks.COBBLESTONE.getDefaultState(), 3);
		world.setBlockState(new BlockPos(x + 0, y + 8, z + 10), Blocks.GRASS.getDefaultState(), 3);
		world.setBlockState(new BlockPos(x + 1, y + 8, z + 10), Blocks.COBBLESTONE.getDefaultState(), 3);
		world.setBlockState(new BlockPos(x + 2, y + 8, z + 10), ModBlocks.red_cable.getDefaultState(), 3);
		world.setBlockState(new BlockPos(x + 3, y + 8, z + 10), Blocks.STAINED_HARDENED_CLAY.getDefaultState().withProperty(BlockStainedHardenedClay.COLOR, EnumDyeColor.byMetadata(0)), 3);
		world.setBlockState(new BlockPos(x + 4, y + 8, z + 10), Blocks.STAINED_HARDENED_CLAY.getDefaultState().withProperty(BlockStainedHardenedClay.COLOR, EnumDyeColor.byMetadata(15)), 3);
		world.setBlockState(new BlockPos(x + 5, y + 8, z + 10), Blocks.AIR.getDefaultState(), 3);
		world.setBlockState(new BlockPos(x + 6, y + 8, z + 10), Blocks.AIR.getDefaultState(), 3);
		world.setBlockState(new BlockPos(x + 7, y + 8, z + 10), Blocks.AIR.getDefaultState(), 3);
		world.setBlockState(new BlockPos(x + 8, y + 8, z + 10), Blocks.AIR.getDefaultState(), 3);
		world.setBlockState(new BlockPos(x + 9, y + 8, z + 10), Blocks.PLANKS.getDefaultState().withProperty(BlockPlanks.VARIANT, BlockPlanks.EnumType.SPRUCE), 3);
		world.setBlockState(new BlockPos(x + 10, y + 8, z + 10), Blocks.PLANKS.getDefaultState().withProperty(BlockPlanks.VARIANT, BlockPlanks.EnumType.SPRUCE), 3);
		world.setBlockState(new BlockPos(x + 11, y + 8, z + 10), Blocks.SPRUCE_STAIRS.getDefaultState().withProperty(BlockStairs.HALF, BlockStairs.EnumHalf.BOTTOM).withProperty(BlockStairs.FACING, EnumFacing.WEST), 3);
		world.setBlockState(new BlockPos(x + 0, y + 8, z + 11), Blocks.GRASS.getDefaultState(), 3);
		world.setBlockState(new BlockPos(x + 1, y + 8, z + 11), Blocks.COBBLESTONE.getDefaultState(), 3);
		world.setBlockState(new BlockPos(x + 2, y + 8, z + 11), Blocks.STAINED_HARDENED_CLAY.getDefaultState().withProperty(BlockStainedHardenedClay.COLOR, EnumDyeColor.byMetadata(0)), 3);
		world.setBlockState(new BlockPos(x + 3, y + 8, z + 11), Blocks.STAINED_HARDENED_CLAY.getDefaultState().withProperty(BlockStainedHardenedClay.COLOR, EnumDyeColor.byMetadata(15)), 3);
		world.setBlockState(new BlockPos(x + 4, y + 8, z + 11), Blocks.AIR.getDefaultState(), 3);
		world.setBlockState(new BlockPos(x + 5, y + 8, z + 11), Blocks.AIR.getDefaultState(), 3);
		world.setBlockState(new BlockPos(x + 6, y + 8, z + 11), Blocks.AIR.getDefaultState(), 3);
		world.setBlockState(new BlockPos(x + 7, y + 8, z + 11), Blocks.AIR.getDefaultState(), 3);
		world.setBlockState(new BlockPos(x + 8, y + 8, z + 11), Blocks.AIR.getDefaultState(), 3);
		world.setBlockState(new BlockPos(x + 9, y + 8, z + 11), Blocks.PLANKS.getDefaultState().withProperty(BlockPlanks.VARIANT, BlockPlanks.EnumType.SPRUCE), 3);
		world.setBlockState(new BlockPos(x + 10, y + 8, z + 11), Blocks.PLANKS.getDefaultState().withProperty(BlockPlanks.VARIANT, BlockPlanks.EnumType.SPRUCE), 3);
		world.setBlockState(new BlockPos(x + 11, y + 8, z + 11), Blocks.COBBLESTONE.getDefaultState(), 3);
		world.setBlockState(new BlockPos(x + 0, y + 8, z + 12), Blocks.GRASS.getDefaultState(), 3);
		world.setBlockState(new BlockPos(x + 1, y + 8, z + 12), Blocks.COBBLESTONE.getDefaultState(), 3);
		world.setBlockState(new BlockPos(x + 2, y + 8, z + 12), ModBlocks.red_cable.getDefaultState(), 3);
		world.setBlockState(new BlockPos(x + 3, y + 8, z + 12), Blocks.STAINED_HARDENED_CLAY.getDefaultState().withProperty(BlockStainedHardenedClay.COLOR, EnumDyeColor.byMetadata(0)), 3);
		world.setBlockState(new BlockPos(x + 4, y + 8, z + 12), Blocks.STAINED_HARDENED_CLAY.getDefaultState().withProperty(BlockStainedHardenedClay.COLOR, EnumDyeColor.byMetadata(15)), 3);
		world.setBlockState(new BlockPos(x + 5, y + 8, z + 12), Blocks.AIR.getDefaultState(), 3);
		world.setBlockState(new BlockPos(x + 6, y + 8, z + 12), Blocks.SPRUCE_STAIRS.getDefaultState().withProperty(BlockStairs.HALF, BlockStairs.EnumHalf.BOTTOM).withProperty(BlockStairs.FACING, EnumFacing.EAST), 3);
		world.setBlockState(new BlockPos(x + 7, y + 8, z + 12), Blocks.SPRUCE_STAIRS.getDefaultState().withProperty(BlockStairs.HALF, BlockStairs.EnumHalf.BOTTOM).withProperty(BlockStairs.FACING, EnumFacing.WEST), 3);
		world.setBlockState(new BlockPos(x + 8, y + 8, z + 12), Blocks.PLANKS.getDefaultState().withProperty(BlockPlanks.VARIANT, BlockPlanks.EnumType.SPRUCE), 3);
		world.setBlockState(new BlockPos(x + 9, y + 8, z + 12), Blocks.PLANKS.getDefaultState().withProperty(BlockPlanks.VARIANT, BlockPlanks.EnumType.SPRUCE), 3);
		world.setBlockState(new BlockPos(x + 10, y + 8, z + 12), Blocks.TRAPDOOR.getDefaultState().withProperty(BlockTrapDoor.FACING, EnumFacing.SOUTH).withProperty(BlockTrapDoor.OPEN, true).withProperty(BlockTrapDoor.HALF, BlockTrapDoor.DoorHalf.TOP), 3);
		world.setBlockState(new BlockPos(x + 11, y + 8, z + 12), Blocks.COBBLESTONE.getDefaultState(), 3);
		world.setBlockState(new BlockPos(x + 0, y + 8, z + 13), Blocks.DIRT.getDefaultState(), 3);
		world.setBlockState(new BlockPos(x + 1, y + 8, z + 13), Blocks.COBBLESTONE.getDefaultState(), 3);
		world.setBlockState(new BlockPos(x + 2, y + 8, z + 13), Blocks.COBBLESTONE.getDefaultState(), 3);
		world.setBlockState(new BlockPos(x + 3, y + 8, z + 13), Blocks.MOSSY_COBBLESTONE.getDefaultState(), 3);
		world.setBlockState(new BlockPos(x + 4, y + 8, z + 13), Blocks.MOSSY_COBBLESTONE.getDefaultState(), 3);
		world.setBlockState(new BlockPos(x + 5, y + 8, z + 13), Blocks.MOSSY_COBBLESTONE.getDefaultState(), 3);
		world.setBlockState(new BlockPos(x + 6, y + 8, z + 13), Blocks.MOSSY_COBBLESTONE.getDefaultState(), 3);
		world.setBlockState(new BlockPos(x + 7, y + 8, z + 13), Blocks.COBBLESTONE.getDefaultState(), 3);
		world.setBlockState(new BlockPos(x + 8, y + 8, z + 13), Blocks.COBBLESTONE.getDefaultState(), 3);
		world.setBlockState(new BlockPos(x + 9, y + 8, z + 13), Blocks.COBBLESTONE.getDefaultState(), 3);
		world.setBlockState(new BlockPos(x + 10, y + 8, z + 13), Blocks.COBBLESTONE.getDefaultState(), 3);
		world.setBlockState(new BlockPos(x + 11, y + 8, z + 13), Blocks.MOSSY_COBBLESTONE.getDefaultState(), 3);
		world.setBlockState(new BlockPos(x + 2, y + 8, z + 14), Blocks.DIRT.getDefaultState(), 3);
		world.setBlockState(new BlockPos(x + 3, y + 8, z + 14), Blocks.GRASS.getDefaultState(), 3);
		world.setBlockState(new BlockPos(x + 4, y + 8, z + 14), Blocks.DIRT.getDefaultState(), 3);
		world.setBlockState(new BlockPos(x + 5, y + 8, z + 14), Blocks.DIRT.getDefaultState(), 3);
		world.setBlockState(new BlockPos(x + 6, y + 8, z + 14), Blocks.DIRT.getDefaultState(), 3);
		world.setBlockState(new BlockPos(x + 7, y + 8, z + 14), Blocks.GRASS.getDefaultState(), 3);
		world.setBlockState(new BlockPos(x + 8, y + 8, z + 14), Blocks.DIRT.getDefaultState(), 3);
		world.setBlockState(new BlockPos(x + 9, y + 8, z + 14), Blocks.DIRT.getDefaultState(), 3);
		world.setBlockState(new BlockPos(x + 10, y + 8, z + 14), Blocks.DIRT.getDefaultState(), 3);
		world.setBlockState(new BlockPos(x + 11, y + 8, z + 14), Blocks.DIRT.getDefaultState(), 3);
		world.setBlockState(new BlockPos(x + 0, y + 9, z + 1), Blocks.AIR.getDefaultState(), 3);
		world.setBlockState(new BlockPos(x + 1, y + 9, z + 1), Blocks.AIR.getDefaultState(), 3);
		world.setBlockState(new BlockPos(x + 2, y + 9, z + 1), Blocks.AIR.getDefaultState(), 3);
		world.setBlockState(new BlockPos(x + 3, y + 9, z + 1), Blocks.AIR.getDefaultState(), 3);
		world.setBlockState(new BlockPos(x + 4, y + 9, z + 1), Blocks.AIR.getDefaultState(), 3);
		world.setBlockState(new BlockPos(x + 5, y + 9, z + 1), Blocks.AIR.getDefaultState(), 3);
		world.setBlockState(new BlockPos(x + 6, y + 9, z + 1), Blocks.AIR.getDefaultState(), 3);
		world.setBlockState(new BlockPos(x + 7, y + 9, z + 1), Blocks.AIR.getDefaultState(), 3);
		world.setBlockState(new BlockPos(x + 8, y + 9, z + 1), Blocks.AIR.getDefaultState(), 3);
		world.setBlockState(new BlockPos(x + 9, y + 9, z + 1), Blocks.AIR.getDefaultState(), 3);
		world.setBlockState(new BlockPos(x + 10, y + 9, z + 1), Blocks.AIR.getDefaultState(), 3);
		world.setBlockState(new BlockPos(x + 11, y + 9, z + 1), Blocks.AIR.getDefaultState(), 3);
		world.setBlockState(new BlockPos(x + 0, y + 9, z + 2), Blocks.AIR.getDefaultState(), 3);
		world.setBlockState(new BlockPos(x + 1, y + 9, z + 2), Blocks.OAK_FENCE.getDefaultState(), 3);
		world.setBlockState(new BlockPos(x + 2, y + 9, z + 2), Blocks.AIR.getDefaultState(), 3);
		world.setBlockState(new BlockPos(x + 3, y + 9, z + 2), Blocks.WOODEN_SLAB.getDefaultState().withProperty(BlockHalfWoodSlab.HALF, BlockSlab.EnumBlockHalf.BOTTOM).withProperty(BlockHalfWoodSlab.VARIANT, BlockPlanks.EnumType.byMetadata(1)), 3);
		world.setBlockState(new BlockPos(x + 4, y + 9, z + 2), Blocks.DOUBLE_WOODEN_SLAB.getDefaultState().withProperty(BlockHalfWoodSlab.VARIANT, BlockPlanks.EnumType.byMetadata(1)), 3);
		world.setBlockState(new BlockPos(x + 5, y + 9, z + 2), Blocks.WOODEN_SLAB.getDefaultState().withProperty(BlockHalfWoodSlab.HALF, BlockSlab.EnumBlockHalf.BOTTOM).withProperty(BlockHalfWoodSlab.VARIANT, BlockPlanks.EnumType.byMetadata(1)), 3);
		world.setBlockState(new BlockPos(x + 6, y + 9, z + 2), Blocks.AIR.getDefaultState(), 3);
		world.setBlockState(new BlockPos(x + 7, y + 9, z + 2), Blocks.WOODEN_SLAB.getDefaultState().withProperty(BlockHalfWoodSlab.HALF, BlockSlab.EnumBlockHalf.BOTTOM).withProperty(BlockHalfWoodSlab.VARIANT, BlockPlanks.EnumType.byMetadata(1)), 3);
		world.setBlockState(new BlockPos(x + 8, y + 9, z + 2), Blocks.AIR.getDefaultState(), 3);
		world.setBlockState(new BlockPos(x + 9, y + 9, z + 2), Blocks.WOODEN_SLAB.getDefaultState().withProperty(BlockHalfWoodSlab.HALF, BlockSlab.EnumBlockHalf.BOTTOM).withProperty(BlockHalfWoodSlab.VARIANT, BlockPlanks.EnumType.byMetadata(1)), 3);
		world.setBlockState(new BlockPos(x + 10, y + 9, z + 2), Blocks.WOODEN_SLAB.getDefaultState().withProperty(BlockHalfWoodSlab.HALF, BlockSlab.EnumBlockHalf.BOTTOM).withProperty(BlockHalfWoodSlab.VARIANT, BlockPlanks.EnumType.byMetadata(1)), 3);
		world.setBlockState(new BlockPos(x + 11, y + 9, z + 2), Blocks.OAK_FENCE.getDefaultState(), 3);
		world.setBlockState(new BlockPos(x + 0, y + 9, z + 3), Blocks.AIR.getDefaultState(), 3);
		world.setBlockState(new BlockPos(x + 1, y + 9, z + 3), Blocks.AIR.getDefaultState(), 3);
		world.setBlockState(new BlockPos(x + 2, y + 9, z + 3), Blocks.WOODEN_SLAB.getDefaultState().withProperty(BlockHalfWoodSlab.HALF, BlockSlab.EnumBlockHalf.BOTTOM).withProperty(BlockHalfWoodSlab.VARIANT, BlockPlanks.EnumType.byMetadata(1)), 3);
		world.setBlockState(new BlockPos(x + 3, y + 9, z + 3), Blocks.DOUBLE_WOODEN_SLAB.getDefaultState().withProperty(BlockHalfWoodSlab.VARIANT, BlockPlanks.EnumType.byMetadata(1)), 3);
		world.setBlockState(new BlockPos(x + 4, y + 9, z + 3), Blocks.AIR.getDefaultState(), 3);
		world.setBlockState(new BlockPos(x + 5, y + 9, z + 3), Blocks.OAK_FENCE.getDefaultState(), 3);
		world.setBlockState(new BlockPos(x + 6, y + 9, z + 3), Blocks.AIR.getDefaultState(), 3);
		world.setBlockState(new BlockPos(x + 7, y + 9, z + 3), Blocks.OAK_FENCE.getDefaultState(), 3);
		world.setBlockState(new BlockPos(x + 8, y + 9, z + 3), Blocks.AIR.getDefaultState(), 3);
		world.setBlockState(new BlockPos(x + 9, y + 9, z + 3), Blocks.DOUBLE_WOODEN_SLAB.getDefaultState().withProperty(BlockHalfWoodSlab.VARIANT, BlockPlanks.EnumType.byMetadata(1)), 3);
		world.setBlockState(new BlockPos(x + 10, y + 9, z + 3), Blocks.AIR.getDefaultState(), 3);
		world.setBlockState(new BlockPos(x + 11, y + 9, z + 3), Blocks.AIR.getDefaultState(), 3);
		world.setBlockState(new BlockPos(x + 12, y + 9, z + 3), Blocks.AIR.getDefaultState(), 3);
		world.setBlockState(new BlockPos(x + 0, y + 9, z + 4), Blocks.AIR.getDefaultState(), 3);
		world.setBlockState(new BlockPos(x + 1, y + 9, z + 4), Blocks.AIR.getDefaultState(), 3);
		world.setBlockState(new BlockPos(x + 2, y + 9, z + 4), Blocks.AIR.getDefaultState(), 3);
		world.setBlockState(new BlockPos(x + 3, y + 9, z + 4), Blocks.AIR.getDefaultState(), 3);
		world.setBlockState(new BlockPos(x + 4, y + 9, z + 4), Blocks.AIR.getDefaultState(), 3);
		world.setBlockState(new BlockPos(x + 5, y + 9, z + 4), Blocks.AIR.getDefaultState(), 3);
		world.setBlockState(new BlockPos(x + 6, y + 9, z + 4), Blocks.AIR.getDefaultState(), 3);
		world.setBlockState(new BlockPos(x + 7, y + 9, z + 4), Blocks.AIR.getDefaultState(), 3);
		world.setBlockState(new BlockPos(x + 8, y + 9, z + 4), Blocks.DOUBLE_WOODEN_SLAB.getDefaultState().withProperty(BlockHalfWoodSlab.VARIANT, BlockPlanks.EnumType.byMetadata(1)), 3);
		world.setBlockState(new BlockPos(x + 9, y + 9, z + 4), Blocks.AIR.getDefaultState(), 3);
		world.setBlockState(new BlockPos(x + 10, y + 9, z + 4), Blocks.AIR.getDefaultState(), 3);
		world.setBlockState(new BlockPos(x + 11, y + 9, z + 4), Blocks.AIR.getDefaultState(), 3);
		world.setBlockState(new BlockPos(x + 12, y + 9, z + 4), Blocks.AIR.getDefaultState(), 3);
		world.setBlockState(new BlockPos(x + 0, y + 9, z + 5), Blocks.AIR.getDefaultState(), 3);
		world.setBlockState(new BlockPos(x + 1, y + 9, z + 5), Blocks.MOSSY_COBBLESTONE.getDefaultState(), 3);
		world.setBlockState(new BlockPos(x + 2, y + 9, z + 5), Blocks.COBBLESTONE.getDefaultState(), 3);
		world.setBlockState(new BlockPos(x + 3, y + 9, z + 5), Blocks.COBBLESTONE.getDefaultState(), 3);
		world.setBlockState(new BlockPos(x + 4, y + 9, z + 5), Blocks.COBBLESTONE.getDefaultState(), 3);
		world.setBlockState(new BlockPos(x + 5, y + 9, z + 5), Blocks.COBBLESTONE.getDefaultState(), 3);
		//Drillgon200: Supposed to be a door apparently. I'll wait for bob to fix it.
		//world.setBlockState(new BlockPos(x + 6, y + 9, z + 5), Blocks.diamond_block, 5, 3);
		world.setBlockState(new BlockPos(x + 7, y + 9, z + 5), Blocks.COBBLESTONE.getDefaultState(), 3);
		world.setBlockState(new BlockPos(x + 8, y + 9, z + 5), Blocks.COBBLESTONE.getDefaultState(), 3);
		world.setBlockState(new BlockPos(x + 9, y + 9, z + 5), Blocks.COBBLESTONE.getDefaultState(), 3);
		world.setBlockState(new BlockPos(x + 10, y + 9, z + 5), Blocks.COBBLESTONE.getDefaultState(), 3);
		world.setBlockState(new BlockPos(x + 11, y + 9, z + 5), Blocks.COBBLESTONE.getDefaultState(), 3);
		world.setBlockState(new BlockPos(x + 12, y + 9, z + 5), Blocks.AIR.getDefaultState(), 3);
		world.setBlockState(new BlockPos(x + 0, y + 9, z + 6), Blocks.AIR.getDefaultState(), 3);
		world.setBlockState(new BlockPos(x + 1, y + 9, z + 6), Blocks.MOSSY_COBBLESTONE.getDefaultState(), 3);
		world.setBlockState(new BlockPos(x + 2, y + 9, z + 6), Blocks.IRON_BLOCK.getDefaultState(), 3);
		//Drillgon200: I hate doors.
		world.setBlockState(new BlockPos(x + 3, y + 9, z + 6), Blocks.IRON_DOOR.getDefaultState(), 3);
		world.setBlockState(new BlockPos(x + 4, y + 9, z + 6), Block4.getDefaultState(), 3);
		world.setBlockState(new BlockPos(x + 5, y + 9, z + 6), Block5.getDefaultState().withProperty(DecoBlock.FACING, EnumFacing.EAST), 3);
		world.setBlockState(new BlockPos(x + 6, y + 9, z + 6), Blocks.AIR.getDefaultState(), 3);
		world.setBlockState(new BlockPos(x + 7, y + 9, z + 6), Blocks.AIR.getDefaultState(), 3);
		world.setBlockState(new BlockPos(x + 8, y + 9, z + 6), Blocks.AIR.getDefaultState(), 3);
		world.setBlockState(new BlockPos(x + 9, y + 9, z + 6), Blocks.AIR.getDefaultState(), 3);
		world.setBlockState(new BlockPos(x + 10, y + 9, z + 6), Blocks.CHEST.getDefaultState().withProperty(BlockChest.FACING, EnumFacing.WEST), 3);
		world.setBlockState(new BlockPos(x + 11, y + 9, z + 6), Blocks.MOSSY_COBBLESTONE.getDefaultState(), 3);
		world.setBlockState(new BlockPos(x + 12, y + 9, z + 6), Blocks.AIR.getDefaultState(), 3);
		world.setBlockState(new BlockPos(x + 0, y + 9, z + 7), Blocks.AIR.getDefaultState(), 3);
		world.setBlockState(new BlockPos(x + 1, y + 9, z + 7), Blocks.MOSSY_COBBLESTONE.getDefaultState(), 3);
		world.setBlockState(new BlockPos(x + 2, y + 9, z + 7), Block4.getDefaultState(), 3);
		world.setBlockState(new BlockPos(x + 3, y + 9, z + 7), Blocks.AIR.getDefaultState(), 3);
		world.setBlockState(new BlockPos(x + 4, y + 9, z + 7), Block4.getDefaultState(), 3);
		world.setBlockState(new BlockPos(x + 5, y + 9, z + 7), Block5.getDefaultState().withProperty(DecoBlock.FACING, EnumFacing.EAST), 3);
		world.setBlockState(new BlockPos(x + 6, y + 9, z + 7), Blocks.AIR.getDefaultState(), 3);
		world.setBlockState(new BlockPos(x + 7, y + 9, z + 7), Blocks.AIR.getDefaultState(), 3);
		world.setBlockState(new BlockPos(x + 8, y + 9, z + 7), Blocks.AIR.getDefaultState(), 3);
		world.setBlockState(new BlockPos(x + 9, y + 9, z + 7), Blocks.AIR.getDefaultState(), 3);
		world.setBlockState(new BlockPos(x + 10, y + 9, z + 7), Blocks.AIR.getDefaultState(), 3);
		world.setBlockState(new BlockPos(x + 11, y + 9, z + 7), Blocks.COBBLESTONE.getDefaultState(), 3);
		world.setBlockState(new BlockPos(x + 12, y + 9, z + 7), Blocks.AIR.getDefaultState(), 3);
		world.setBlockState(new BlockPos(x + 0, y + 9, z + 8), Blocks.AIR.getDefaultState(), 3);
		world.setBlockState(new BlockPos(x + 1, y + 9, z + 8), Blocks.COBBLESTONE.getDefaultState(), 3);
		world.setBlockState(new BlockPos(x + 2, y + 9, z + 8), Blocks.CAULDRON.getDefaultState().withProperty(BlockCauldron.LEVEL, 3), 3);
		world.setBlockState(new BlockPos(x + 3, y + 9, z + 8), Blocks.AIR.getDefaultState(), 3);
		world.setBlockState(new BlockPos(x + 4, y + 9, z + 8), Block4.getDefaultState(), 3);
		world.setBlockState(new BlockPos(x + 5, y + 9, z + 8), Block5.getDefaultState().withProperty(DecoBlock.FACING, EnumFacing.EAST), 3);
		world.setBlockState(new BlockPos(x + 6, y + 9, z + 8), Blocks.AIR.getDefaultState(), 3);
		world.setBlockState(new BlockPos(x + 7, y + 9, z + 8), Blocks.AIR.getDefaultState(), 3);
		world.setBlockState(new BlockPos(x + 8, y + 9, z + 8), Blocks.AIR.getDefaultState(), 3);
		world.setBlockState(new BlockPos(x + 9, y + 9, z + 8), Blocks.AIR.getDefaultState(), 3);
		world.setBlockState(new BlockPos(x + 10, y + 9, z + 8), Blocks.AIR.getDefaultState(), 3);
		world.setBlockState(new BlockPos(x + 11, y + 9, z + 8), Blocks.MOSSY_COBBLESTONE.getDefaultState(), 3);
		world.setBlockState(new BlockPos(x + 12, y + 9, z + 8), Blocks.AIR.getDefaultState(), 3);
		world.setBlockState(new BlockPos(x + 1, y + 9, z + 9), Blocks.COBBLESTONE.getDefaultState(), 3);
		world.setBlockState(new BlockPos(x + 2, y + 9, z + 9), Block4.getDefaultState(), 3);
		world.setBlockState(new BlockPos(x + 3, y + 9, z + 9), Blocks.AIR.getDefaultState(), 3);
		world.setBlockState(new BlockPos(x + 4, y + 9, z + 9), Block4.getDefaultState(), 3);
		world.setBlockState(new BlockPos(x + 5, y + 9, z + 9), Block5.getDefaultState().withProperty(DecoBlock.FACING, EnumFacing.EAST), 3);
		world.setBlockState(new BlockPos(x + 6, y + 9, z + 9), Blocks.AIR.getDefaultState(), 3);
		world.setBlockState(new BlockPos(x + 7, y + 9, z + 9), Blocks.AIR.getDefaultState(), 3);
		world.setBlockState(new BlockPos(x + 8, y + 9, z + 9), Blocks.AIR.getDefaultState(), 3);
		world.setBlockState(new BlockPos(x + 9, y + 9, z + 9), Blocks.AIR.getDefaultState(), 3);
		world.setBlockState(new BlockPos(x + 10, y + 9, z + 9), Blocks.AIR.getDefaultState(), 3);
		world.setBlockState(new BlockPos(x + 11, y + 9, z + 9), Blocks.MOSSY_COBBLESTONE.getDefaultState(), 3);
		world.setBlockState(new BlockPos(x + 12, y + 9, z + 9), Blocks.AIR.getDefaultState(), 3);
		world.setBlockState(new BlockPos(x + 1, y + 9, z + 10), Blocks.MOSSY_COBBLESTONE.getDefaultState(), 3);
		world.setBlockState(new BlockPos(x + 2, y + 9, z + 10), Blocks.LIT_REDSTONE_LAMP.getDefaultState(), 3);
		world.setBlockState(new BlockPos(x + 3, y + 9, z + 10), Blocks.AIR.getDefaultState(), 3);
		world.setBlockState(new BlockPos(x + 4, y + 9, z + 10), Blocks.AIR.getDefaultState(), 3);
		world.setBlockState(new BlockPos(x + 5, y + 9, z + 10), Blocks.AIR.getDefaultState(), 3);
		world.setBlockState(new BlockPos(x + 6, y + 9, z + 10), Blocks.AIR.getDefaultState(), 3);
		world.setBlockState(new BlockPos(x + 7, y + 9, z + 10), Blocks.AIR.getDefaultState(), 3);
		world.setBlockState(new BlockPos(x + 8, y + 9, z + 10), Blocks.AIR.getDefaultState(), 3);
		world.setBlockState(new BlockPos(x + 9, y + 9, z + 10), Blocks.SPRUCE_STAIRS.getDefaultState().withProperty(BlockStairs.HALF, BlockStairs.EnumHalf.BOTTOM).withProperty(BlockStairs.FACING, EnumFacing.WEST), 3);
		world.setBlockState(new BlockPos(x + 10, y + 9, z + 10), Blocks.NETHER_BRICK_FENCE.getDefaultState(), 3);
		world.setBlockState(new BlockPos(x + 11, y + 9, z + 10), Blocks.MOSSY_COBBLESTONE.getDefaultState(), 3);
		world.setBlockState(new BlockPos(x + 12, y + 9, z + 10), Blocks.AIR.getDefaultState(), 3);
		world.setBlockState(new BlockPos(x + 1, y + 9, z + 11), Blocks.MOSSY_COBBLESTONE.getDefaultState(), 3);
		world.setBlockState(new BlockPos(x + 2, y + 9, z + 11), Block4.getDefaultState(), 3);
		world.setBlockState(new BlockPos(x + 3, y + 9, z + 11), Blocks.AIR.getDefaultState(), 3);
		world.setBlockState(new BlockPos(x + 4, y + 9, z + 11), Blocks.AIR.getDefaultState(), 3);
		world.setBlockState(new BlockPos(x + 5, y + 9, z + 11), Blocks.AIR.getDefaultState(), 3);
		world.setBlockState(new BlockPos(x + 6, y + 9, z + 11), Blocks.AIR.getDefaultState(), 3);
		world.setBlockState(new BlockPos(x + 7, y + 9, z + 11), Blocks.AIR.getDefaultState(), 3);
		world.setBlockState(new BlockPos(x + 8, y + 9, z + 11), Blocks.AIR.getDefaultState(), 3);
		world.setBlockState(new BlockPos(x + 9, y + 9, z + 11), Blocks.SPRUCE_STAIRS.getDefaultState().withProperty(BlockStairs.HALF, BlockStairs.EnumHalf.BOTTOM).withProperty(BlockStairs.FACING, EnumFacing.WEST), 3);
		world.setBlockState(new BlockPos(x + 10, y + 9, z + 11), Blocks.NETHER_BRICK_FENCE.getDefaultState(), 3);
		world.setBlockState(new BlockPos(x + 11, y + 9, z + 11), Blocks.COBBLESTONE.getDefaultState(), 3);
		world.setBlockState(new BlockPos(x + 12, y + 9, z + 11), Blocks.AIR.getDefaultState(), 3);
		world.setBlockState(new BlockPos(x + 1, y + 9, z + 12), Blocks.MOSSY_COBBLESTONE.getDefaultState(), 3);
		world.setBlockState(new BlockPos(x + 2, y + 9, z + 12), Blocks.LIT_REDSTONE_LAMP.getDefaultState(), 3);
		world.setBlockState(new BlockPos(x + 3, y + 9, z + 12), Blocks.AIR.getDefaultState(), 3);
		world.setBlockState(new BlockPos(x + 4, y + 9, z + 12), Blocks.AIR.getDefaultState(), 3);
		world.setBlockState(new BlockPos(x + 5, y + 9, z + 12), Blocks.AIR.getDefaultState(), 3);
		world.setBlockState(new BlockPos(x + 6, y + 9, z + 12), Blocks.AIR.getDefaultState(), 3);
		world.setBlockState(new BlockPos(x + 7, y + 9, z + 12), Blocks.AIR.getDefaultState(), 3);
		world.setBlockState(new BlockPos(x + 8, y + 9, z + 12), Blocks.AIR.getDefaultState(), 3);
		world.setBlockState(new BlockPos(x + 9, y + 9, z + 12), Blocks.AIR.getDefaultState(), 3);
		world.setBlockState(new BlockPos(x + 10, y + 9, z + 12), Blocks.AIR.getDefaultState(), 3);
		world.setBlockState(new BlockPos(x + 11, y + 9, z + 12), Blocks.SPRUCE_STAIRS.getDefaultState().withProperty(BlockStairs.HALF, BlockStairs.EnumHalf.TOP).withProperty(BlockStairs.FACING, EnumFacing.EAST), 3);
		world.setBlockState(new BlockPos(x + 12, y + 9, z + 12), Blocks.AIR.getDefaultState(), 3);
		world.setBlockState(new BlockPos(x + 0, y + 9, z + 13), Blocks.AIR.getDefaultState(), 3);
		world.setBlockState(new BlockPos(x + 1, y + 9, z + 13), Blocks.COBBLESTONE.getDefaultState(), 3);
		world.setBlockState(new BlockPos(x + 2, y + 9, z + 13), Blocks.COBBLESTONE.getDefaultState(), 3);
		world.setBlockState(new BlockPos(x + 3, y + 9, z + 13), Blocks.COBBLESTONE.getDefaultState(), 3);
		world.setBlockState(new BlockPos(x + 4, y + 9, z + 13), Blocks.SPRUCE_STAIRS.getDefaultState().withProperty(BlockStairs.HALF, BlockStairs.EnumHalf.BOTTOM).withProperty(BlockStairs.FACING, EnumFacing.NORTH), 3);
		world.setBlockState(new BlockPos(x + 5, y + 9, z + 13), Blocks.MOSSY_COBBLESTONE.getDefaultState(), 3);
		world.setBlockState(new BlockPos(x + 6, y + 9, z + 13), Blocks.MOSSY_COBBLESTONE.getDefaultState(), 3);
		world.setBlockState(new BlockPos(x + 7, y + 9, z + 13), Blocks.COBBLESTONE.getDefaultState(), 3);
		world.setBlockState(new BlockPos(x + 8, y + 9, z + 13), Blocks.MOSSY_COBBLESTONE.getDefaultState(), 3);
		world.setBlockState(new BlockPos(x + 9, y + 9, z + 13), Blocks.MOSSY_COBBLESTONE.getDefaultState(), 3);
		world.setBlockState(new BlockPos(x + 10, y + 9, z + 13), Blocks.MOSSY_COBBLESTONE.getDefaultState(), 3);
		world.setBlockState(new BlockPos(x + 11, y + 9, z + 13), Blocks.COBBLESTONE.getDefaultState(), 3);
		world.setBlockState(new BlockPos(x + 12, y + 9, z + 13), Blocks.AIR.getDefaultState(), 3);
		world.setBlockState(new BlockPos(x + 1, y + 9, z + 14), Blocks.AIR.getDefaultState(), 3);
		world.setBlockState(new BlockPos(x + 2, y + 9, z + 14), Blocks.AIR.getDefaultState(), 3);
		world.setBlockState(new BlockPos(x + 4, y + 9, z + 14), Blocks.AIR.getDefaultState(), 3);
		world.setBlockState(new BlockPos(x + 5, y + 9, z + 14), Blocks.AIR.getDefaultState(), 3);
		world.setBlockState(new BlockPos(x + 6, y + 9, z + 14), Blocks.AIR.getDefaultState(), 3);
		world.setBlockState(new BlockPos(x + 8, y + 9, z + 14), Blocks.AIR.getDefaultState(), 3);
		world.setBlockState(new BlockPos(x + 9, y + 9, z + 14), Blocks.AIR.getDefaultState(), 3);
		world.setBlockState(new BlockPos(x + 10, y + 9, z + 14), Blocks.AIR.getDefaultState(), 3);
		world.setBlockState(new BlockPos(x + 11, y + 9, z + 14), Blocks.AIR.getDefaultState(), 3);
		world.setBlockState(new BlockPos(x + 0, y + 10, z + 1), Blocks.AIR.getDefaultState(), 3);
		world.setBlockState(new BlockPos(x + 1, y + 10, z + 1), Blocks.AIR.getDefaultState(), 3);
		world.setBlockState(new BlockPos(x + 2, y + 10, z + 1), Blocks.AIR.getDefaultState(), 3);
		world.setBlockState(new BlockPos(x + 3, y + 10, z + 1), Blocks.AIR.getDefaultState(), 3);
		world.setBlockState(new BlockPos(x + 4, y + 10, z + 1), Blocks.AIR.getDefaultState(), 3);
		world.setBlockState(new BlockPos(x + 5, y + 10, z + 1), Blocks.AIR.getDefaultState(), 3);
		world.setBlockState(new BlockPos(x + 6, y + 10, z + 1), Blocks.AIR.getDefaultState(), 3);
		world.setBlockState(new BlockPos(x + 7, y + 10, z + 1), Blocks.AIR.getDefaultState(), 3);
		world.setBlockState(new BlockPos(x + 8, y + 10, z + 1), Blocks.AIR.getDefaultState(), 3);
		world.setBlockState(new BlockPos(x + 9, y + 10, z + 1), Blocks.AIR.getDefaultState(), 3);
		world.setBlockState(new BlockPos(x + 10, y + 10, z + 1), Blocks.AIR.getDefaultState(), 3);
		world.setBlockState(new BlockPos(x + 11, y + 10, z + 1), Blocks.AIR.getDefaultState(), 3);
		world.setBlockState(new BlockPos(x + 0, y + 10, z + 2), Blocks.AIR.getDefaultState(), 3);
		world.setBlockState(new BlockPos(x + 1, y + 10, z + 2), Blocks.OAK_FENCE.getDefaultState(), 3);
		world.setBlockState(new BlockPos(x + 2, y + 10, z + 2), Blocks.AIR.getDefaultState(), 3);
		world.setBlockState(new BlockPos(x + 3, y + 10, z + 2), Blocks.AIR.getDefaultState(), 3);
		world.setBlockState(new BlockPos(x + 4, y + 10, z + 2), Blocks.AIR.getDefaultState(), 3);
		world.setBlockState(new BlockPos(x + 5, y + 10, z + 2), Blocks.AIR.getDefaultState(), 3);
		world.setBlockState(new BlockPos(x + 6, y + 10, z + 2), Blocks.AIR.getDefaultState(), 3);
		world.setBlockState(new BlockPos(x + 7, y + 10, z + 2), Blocks.AIR.getDefaultState(), 3);
		world.setBlockState(new BlockPos(x + 8, y + 10, z + 2), Blocks.AIR.getDefaultState(), 3);
		world.setBlockState(new BlockPos(x + 9, y + 10, z + 2), Blocks.AIR.getDefaultState(), 3);
		world.setBlockState(new BlockPos(x + 10, y + 10, z + 2), Blocks.AIR.getDefaultState(), 3);
		world.setBlockState(new BlockPos(x + 11, y + 10, z + 2), Blocks.OAK_FENCE.getDefaultState(), 3);
		world.setBlockState(new BlockPos(x + 0, y + 10, z + 3), Blocks.AIR.getDefaultState(), 3);
		world.setBlockState(new BlockPos(x + 1, y + 10, z + 3), Blocks.AIR.getDefaultState(), 3);
		world.setBlockState(new BlockPos(x + 2, y + 10, z + 3), Blocks.AIR.getDefaultState(), 3);
		world.setBlockState(new BlockPos(x + 3, y + 10, z + 3), Blocks.AIR.getDefaultState(), 3);
		world.setBlockState(new BlockPos(x + 4, y + 10, z + 3), Blocks.AIR.getDefaultState(), 3);
		world.setBlockState(new BlockPos(x + 5, y + 10, z + 3), Blocks.OAK_FENCE.getDefaultState(), 3);
		world.setBlockState(new BlockPos(x + 6, y + 10, z + 3), Blocks.AIR.getDefaultState(), 3);
		world.setBlockState(new BlockPos(x + 7, y + 10, z + 3), Blocks.OAK_FENCE.getDefaultState(), 3);
		world.setBlockState(new BlockPos(x + 8, y + 10, z + 3), Blocks.AIR.getDefaultState(), 3);
		world.setBlockState(new BlockPos(x + 9, y + 10, z + 3), Blocks.WOODEN_SLAB.getDefaultState().withProperty(BlockHalfWoodSlab.HALF, BlockSlab.EnumBlockHalf.BOTTOM).withProperty(BlockHalfWoodSlab.VARIANT, BlockPlanks.EnumType.byMetadata(1)), 3);
		world.setBlockState(new BlockPos(x + 10, y + 10, z + 3), Blocks.AIR.getDefaultState(), 3);
		world.setBlockState(new BlockPos(x + 11, y + 10, z + 3), Blocks.AIR.getDefaultState(), 3);
		world.setBlockState(new BlockPos(x + 12, y + 10, z + 3), Blocks.AIR.getDefaultState(), 3);
		world.setBlockState(new BlockPos(x + 0, y + 10, z + 4), Blocks.AIR.getDefaultState(), 3);
		world.setBlockState(new BlockPos(x + 1, y + 10, z + 4), Blocks.AIR.getDefaultState(), 3);
		world.setBlockState(new BlockPos(x + 2, y + 10, z + 4), Blocks.AIR.getDefaultState(), 3);
		world.setBlockState(new BlockPos(x + 3, y + 10, z + 4), Blocks.AIR.getDefaultState(), 3);
		world.setBlockState(new BlockPos(x + 4, y + 10, z + 4), Blocks.AIR.getDefaultState(), 3);
		world.setBlockState(new BlockPos(x + 5, y + 10, z + 4), Blocks.AIR.getDefaultState(), 3);
		world.setBlockState(new BlockPos(x + 6, y + 10, z + 4), Blocks.AIR.getDefaultState(), 3);
		world.setBlockState(new BlockPos(x + 7, y + 10, z + 4), Blocks.AIR.getDefaultState(), 3);
		world.setBlockState(new BlockPos(x + 8, y + 10, z + 4), Blocks.AIR.getDefaultState(), 3);
		world.setBlockState(new BlockPos(x + 9, y + 10, z + 4), Blocks.AIR.getDefaultState(), 3);
		world.setBlockState(new BlockPos(x + 10, y + 10, z + 4), Blocks.AIR.getDefaultState(), 3);
		world.setBlockState(new BlockPos(x + 11, y + 10, z + 4), Blocks.AIR.getDefaultState(), 3);
		world.setBlockState(new BlockPos(x + 12, y + 10, z + 4), Blocks.AIR.getDefaultState(), 3);
		world.setBlockState(new BlockPos(x + 0, y + 10, z + 5), Blocks.AIR.getDefaultState(), 3);
		world.setBlockState(new BlockPos(x + 1, y + 10, z + 5), Blocks.COBBLESTONE.getDefaultState(), 3);
		world.setBlockState(new BlockPos(x + 2, y + 10, z + 5), Blocks.STONE_STAIRS.getDefaultState().withProperty(BlockStairs.HALF, BlockStairs.EnumHalf.BOTTOM).withProperty(BlockStairs.FACING, EnumFacing.SOUTH), 3);
		world.setBlockState(new BlockPos(x + 3, y + 10, z + 5), Blocks.STONE_STAIRS.getDefaultState().withProperty(BlockStairs.HALF, BlockStairs.EnumHalf.BOTTOM).withProperty(BlockStairs.FACING, EnumFacing.SOUTH), 3);
		world.setBlockState(new BlockPos(x + 4, y + 10, z + 5), Blocks.STONE_SLAB.getDefaultState().withProperty(BlockStoneSlab.HALF, BlockSlab.EnumBlockHalf.BOTTOM).withProperty(BlockStoneSlab.VARIANT, BlockStoneSlab.EnumType.byMetadata(3)), 3);
		world.setBlockState(new BlockPos(x + 5, y + 10, z + 5), Blocks.COBBLESTONE.getDefaultState(), 3);
		//world.setBlock(x + 6, y + 10, z + 5, Blocks.diamond_block, 8, 3);
		world.setBlockState(new BlockPos(x + 7, y + 10, z + 5), Blocks.STONE_STAIRS.getDefaultState().withProperty(BlockStairs.HALF, BlockStairs.EnumHalf.BOTTOM).withProperty(BlockStairs.FACING, EnumFacing.SOUTH), 3);
		world.setBlockState(new BlockPos(x + 8, y + 10, z + 5), Blocks.AIR.getDefaultState(), 3);
		world.setBlockState(new BlockPos(x + 9, y + 10, z + 5), Blocks.STONE_SLAB.getDefaultState().withProperty(BlockStoneSlab.HALF, BlockSlab.EnumBlockHalf.BOTTOM).withProperty(BlockStoneSlab.VARIANT, BlockStoneSlab.EnumType.byMetadata(3)), 3);
		world.setBlockState(new BlockPos(x + 10, y + 10, z + 5), Blocks.COBBLESTONE.getDefaultState(), 3);
		world.setBlockState(new BlockPos(x + 11, y + 10, z + 5), Blocks.COBBLESTONE.getDefaultState(), 3);
		world.setBlockState(new BlockPos(x + 12, y + 10, z + 5), Blocks.AIR.getDefaultState(), 3);
		world.setBlockState(new BlockPos(x + 0, y + 10, z + 6), Blocks.AIR.getDefaultState(), 3);
		world.setBlockState(new BlockPos(x + 1, y + 10, z + 6), Blocks.COBBLESTONE.getDefaultState(), 3);
		world.setBlockState(new BlockPos(x + 2, y + 10, z + 6), Blocks.DISPENSER.getDefaultState().withProperty(BlockDispenser.FACING, EnumFacing.EAST).withProperty(BlockDispenser.TRIGGERED, false), 3);
		//world.setBlock(x + 3, y + 10, z + 6, Blocks.iron_door, 8, 3);
		world.setBlockState(new BlockPos(x + 4, y + 10, z + 6), Blocks.FLOWER_POT.getDefaultState(), 3);
		world.setBlockState(new BlockPos(x + 5, y + 10, z + 6), Blocks.AIR.getDefaultState(), 3);
		world.setBlockState(new BlockPos(x + 6, y + 10, z + 6), Blocks.AIR.getDefaultState(), 3);
		world.setBlockState(new BlockPos(x + 7, y + 10, z + 6), Blocks.AIR.getDefaultState(), 3);
		world.setBlockState(new BlockPos(x + 8, y + 10, z + 6), Blocks.AIR.getDefaultState(), 3);
		world.setBlockState(new BlockPos(x + 9, y + 10, z + 6), Blocks.AIR.getDefaultState(), 3);
		world.setBlockState(new BlockPos(x + 10, y + 10, z + 6), Blocks.AIR.getDefaultState(), 3);
		world.setBlockState(new BlockPos(x + 11, y + 10, z + 6), Blocks.COBBLESTONE.getDefaultState(), 3);
		world.setBlockState(new BlockPos(x + 12, y + 10, z + 6), Blocks.AIR.getDefaultState(), 3);
		world.setBlockState(new BlockPos(x + 0, y + 10, z + 7), Blocks.AIR.getDefaultState(), 3);
		world.setBlockState(new BlockPos(x + 1, y + 10, z + 7), Blocks.COBBLESTONE.getDefaultState(), 3);
		world.setBlockState(new BlockPos(x + 3, y + 10, z + 7), Blocks.AIR.getDefaultState(), 3);
		world.setBlockState(new BlockPos(x + 4, y + 10, z + 7), Blocks.AIR.getDefaultState(), 3);
		world.setBlockState(new BlockPos(x + 5, y + 10, z + 7), Blocks.AIR.getDefaultState(), 3);
		world.setBlockState(new BlockPos(x + 6, y + 10, z + 7), Blocks.AIR.getDefaultState(), 3);
		world.setBlockState(new BlockPos(x + 7, y + 10, z + 7), Blocks.AIR.getDefaultState(), 3);
		world.setBlockState(new BlockPos(x + 8, y + 10, z + 7), Blocks.AIR.getDefaultState(), 3);
		world.setBlockState(new BlockPos(x + 9, y + 10, z + 7), Blocks.AIR.getDefaultState(), 3);
		world.setBlockState(new BlockPos(x + 11, y + 10, z + 7), Blocks.COBBLESTONE.getDefaultState(), 3);
		world.setBlockState(new BlockPos(x + 12, y + 10, z + 7), Blocks.AIR.getDefaultState(), 3);
		world.setBlockState(new BlockPos(x + 0, y + 10, z + 8), Blocks.AIR.getDefaultState(), 3);
		world.setBlockState(new BlockPos(x + 1, y + 10, z + 8), Blocks.COBBLESTONE.getDefaultState(), 3);
		world.setBlockState(new BlockPos(x + 3, y + 10, z + 8), Blocks.AIR.getDefaultState(), 3);
		world.setBlockState(new BlockPos(x + 4, y + 10, z + 8), Blocks.AIR.getDefaultState(), 3);
		world.setBlockState(new BlockPos(x + 5, y + 10, z + 8), Blocks.AIR.getDefaultState(), 3);
		world.setBlockState(new BlockPos(x + 6, y + 10, z + 8), Blocks.AIR.getDefaultState(), 3);
		world.setBlockState(new BlockPos(x + 7, y + 10, z + 8), Blocks.AIR.getDefaultState(), 3);
		world.setBlockState(new BlockPos(x + 8, y + 10, z + 8), Blocks.AIR.getDefaultState(), 3);
		world.setBlockState(new BlockPos(x + 9, y + 10, z + 8), Blocks.AIR.getDefaultState(), 3);
		world.setBlockState(new BlockPos(x + 10, y + 10, z + 8), Blocks.AIR.getDefaultState(), 3);
		world.setBlockState(new BlockPos(x + 11, y + 10, z + 8), Blocks.STONE_STAIRS.getDefaultState().withProperty(BlockStairs.HALF, BlockStairs.EnumHalf.TOP).withProperty(BlockStairs.FACING, EnumFacing.EAST), 3);
		world.setBlockState(new BlockPos(x + 12, y + 10, z + 8), Blocks.AIR.getDefaultState(), 3);
		world.setBlockState(new BlockPos(x + 0, y + 10, z + 9), Blocks.AIR.getDefaultState(), 3);
		world.setBlockState(new BlockPos(x + 1, y + 10, z + 9), Blocks.COBBLESTONE.getDefaultState(), 3);
		world.setBlockState(new BlockPos(x + 3, y + 10, z + 9), Blocks.AIR.getDefaultState(), 3);
		world.setBlockState(new BlockPos(x + 4, y + 10, z + 9), Blocks.AIR.getDefaultState(), 3);
		world.setBlockState(new BlockPos(x + 5, y + 10, z + 9), Blocks.AIR.getDefaultState(), 3);
		world.setBlockState(new BlockPos(x + 6, y + 10, z + 9), Blocks.AIR.getDefaultState(), 3);
		world.setBlockState(new BlockPos(x + 7, y + 10, z + 9), Blocks.AIR.getDefaultState(), 3);
		world.setBlockState(new BlockPos(x + 8, y + 10, z + 9), Blocks.AIR.getDefaultState(), 3);
		world.setBlockState(new BlockPos(x + 9, y + 10, z + 9), Blocks.AIR.getDefaultState(), 3);
		world.setBlockState(new BlockPos(x + 10, y + 10, z + 9), Blocks.AIR.getDefaultState(), 3);
		world.setBlockState(new BlockPos(x + 11, y + 10, z + 9), Blocks.STONE_STAIRS.getDefaultState().withProperty(BlockStairs.HALF, BlockStairs.EnumHalf.BOTTOM).withProperty(BlockStairs.FACING, EnumFacing.EAST), 3);
		world.setBlockState(new BlockPos(x + 12, y + 10, z + 9), Blocks.AIR.getDefaultState(), 3);
		world.setBlockState(new BlockPos(x + 1, y + 10, z + 10), Blocks.STONE_SLAB.getDefaultState().withProperty(BlockStoneSlab.HALF, BlockSlab.EnumBlockHalf.BOTTOM).withProperty(BlockStoneSlab.VARIANT, BlockStoneSlab.EnumType.byMetadata(3)), 3);
		world.setBlockState(new BlockPos(x + 2, y + 10, z + 10), Blocks.AIR.getDefaultState(), 3);
		world.setBlockState(new BlockPos(x + 3, y + 10, z + 10), Blocks.AIR.getDefaultState(), 3);
		world.setBlockState(new BlockPos(x + 4, y + 10, z + 10), Blocks.AIR.getDefaultState(), 3);
		world.setBlockState(new BlockPos(x + 5, y + 10, z + 10), Blocks.AIR.getDefaultState(), 3);
		world.setBlockState(new BlockPos(x + 6, y + 10, z + 10), Blocks.AIR.getDefaultState(), 3);
		world.setBlockState(new BlockPos(x + 7, y + 10, z + 10), Blocks.AIR.getDefaultState(), 3);
		world.setBlockState(new BlockPos(x + 8, y + 10, z + 10), Blocks.AIR.getDefaultState(), 3);
		world.setBlockState(new BlockPos(x + 9, y + 10, z + 10), Blocks.AIR.getDefaultState(), 3);
		world.setBlockState(new BlockPos(x + 10, y + 10, z + 10), Blocks.WOODEN_SLAB.getDefaultState().withProperty(BlockHalfWoodSlab.HALF, BlockSlab.EnumBlockHalf.BOTTOM).withProperty(BlockHalfWoodSlab.VARIANT, BlockPlanks.EnumType.byMetadata(1)), 3);
		world.setBlockState(new BlockPos(x + 11, y + 10, z + 10), Blocks.STONE_STAIRS.getDefaultState().withProperty(BlockStairs.HALF, BlockStairs.EnumHalf.TOP).withProperty(BlockStairs.FACING, EnumFacing.EAST), 3);
		world.setBlockState(new BlockPos(x + 12, y + 10, z + 10), Blocks.AIR.getDefaultState(), 3);
		world.setBlockState(new BlockPos(x + 0, y + 10, z + 11), Blocks.AIR.getDefaultState(), 3);
		world.setBlockState(new BlockPos(x + 1, y + 10, z + 11), Blocks.COBBLESTONE.getDefaultState(), 3);
		world.setBlockState(new BlockPos(x + 2, y + 10, z + 11), Blocks.AIR.getDefaultState(), 3);
		world.setBlockState(new BlockPos(x + 3, y + 10, z + 11), Blocks.AIR.getDefaultState(), 3);
		world.setBlockState(new BlockPos(x + 4, y + 10, z + 11), Blocks.AIR.getDefaultState(), 3);
		world.setBlockState(new BlockPos(x + 5, y + 10, z + 11), Blocks.AIR.getDefaultState(), 3);
		world.setBlockState(new BlockPos(x + 6, y + 10, z + 11), Blocks.AIR.getDefaultState(), 3);
		world.setBlockState(new BlockPos(x + 7, y + 10, z + 11), Blocks.AIR.getDefaultState(), 3);
		world.setBlockState(new BlockPos(x + 8, y + 10, z + 11), Blocks.AIR.getDefaultState(), 3);
		world.setBlockState(new BlockPos(x + 9, y + 10, z + 11), Blocks.AIR.getDefaultState(), 3);
		world.setBlockState(new BlockPos(x + 10, y + 10, z + 11), Blocks.WOODEN_SLAB.getDefaultState().withProperty(BlockHalfWoodSlab.HALF, BlockSlab.EnumBlockHalf.BOTTOM).withProperty(BlockHalfWoodSlab.VARIANT, BlockPlanks.EnumType.byMetadata(1)), 3);
		world.setBlockState(new BlockPos(x + 11, y + 10, z + 11), Blocks.COBBLESTONE.getDefaultState(), 3);
		world.setBlockState(new BlockPos(x + 12, y + 10, z + 11), Blocks.AIR.getDefaultState(), 3);
		world.setBlockState(new BlockPos(x + 0, y + 10, z + 12), Blocks.AIR.getDefaultState(), 3);
		world.setBlockState(new BlockPos(x + 1, y + 10, z + 12), Blocks.COBBLESTONE.getDefaultState(), 3);
		world.setBlockState(new BlockPos(x + 2, y + 10, z + 12), Blocks.AIR.getDefaultState(), 3);
		world.setBlockState(new BlockPos(x + 3, y + 10, z + 12), Blocks.AIR.getDefaultState(), 3);
		world.setBlockState(new BlockPos(x + 4, y + 10, z + 12), Blocks.AIR.getDefaultState(), 3);
		world.setBlockState(new BlockPos(x + 5, y + 10, z + 12), Blocks.AIR.getDefaultState(), 3);
		world.setBlockState(new BlockPos(x + 6, y + 10, z + 12), Blocks.AIR.getDefaultState(), 3);
		world.setBlockState(new BlockPos(x + 7, y + 10, z + 12), Blocks.AIR.getDefaultState(), 3);
		world.setBlockState(new BlockPos(x + 8, y + 10, z + 12), Blocks.AIR.getDefaultState(), 3);
		world.setBlockState(new BlockPos(x + 9, y + 10, z + 12), Blocks.AIR.getDefaultState(), 3);
		world.setBlockState(new BlockPos(x + 10, y + 10, z + 12), Blocks.AIR.getDefaultState(), 3);
		world.setBlockState(new BlockPos(x + 11, y + 10, z + 12), Blocks.STONE_SLAB.getDefaultState().withProperty(BlockStoneSlab.HALF, BlockSlab.EnumBlockHalf.BOTTOM).withProperty(BlockStoneSlab.VARIANT, BlockStoneSlab.EnumType.byMetadata(3)), 3);
		world.setBlockState(new BlockPos(x + 12, y + 10, z + 12), Blocks.AIR.getDefaultState(), 3);
		world.setBlockState(new BlockPos(x + 0, y + 10, z + 13), Blocks.AIR.getDefaultState(), 3);
		world.setBlockState(new BlockPos(x + 1, y + 10, z + 13), Blocks.COBBLESTONE.getDefaultState(), 3);
		world.setBlockState(new BlockPos(x + 2, y + 10, z + 13), Blocks.COBBLESTONE.getDefaultState(), 3);
		world.setBlockState(new BlockPos(x + 3, y + 10, z + 13), Blocks.STONE_STAIRS.getDefaultState().withProperty(BlockStairs.HALF, BlockStairs.EnumHalf.TOP).withProperty(BlockStairs.FACING, EnumFacing.NORTH), 3);
		world.setBlockState(new BlockPos(x + 4, y + 10, z + 13), Blocks.COBBLESTONE.getDefaultState(), 3);
		world.setBlockState(new BlockPos(x + 5, y + 10, z + 13), Blocks.STAINED_GLASS.getDefaultState().withProperty(BlockStainedGlass.COLOR, EnumDyeColor.byMetadata(0)), 3);
		world.setBlockState(new BlockPos(x + 6, y + 10, z + 13), Blocks.AIR.getDefaultState().withProperty(BlockStainedGlass.COLOR, EnumDyeColor.byMetadata(0)), 3);
		world.setBlockState(new BlockPos(x + 7, y + 10, z + 13), Blocks.STAINED_GLASS.getDefaultState(), 3);
		world.setBlockState(new BlockPos(x + 8, y + 10, z + 13), Blocks.COBBLESTONE.getDefaultState(), 3);
		world.setBlockState(new BlockPos(x + 9, y + 10, z + 13), Blocks.COBBLESTONE.getDefaultState(), 3);
		world.setBlockState(new BlockPos(x + 10, y + 10, z + 13), Blocks.COBBLESTONE.getDefaultState(), 3);
		world.setBlockState(new BlockPos(x + 11, y + 10, z + 13), Blocks.COBBLESTONE.getDefaultState(), 3);
		world.setBlockState(new BlockPos(x + 12, y + 10, z + 13), Blocks.AIR.getDefaultState(), 3);
		world.setBlockState(new BlockPos(x + 1, y + 10, z + 14), Blocks.AIR.getDefaultState(), 3);
		world.setBlockState(new BlockPos(x + 2, y + 10, z + 14), Blocks.AIR.getDefaultState(), 3);
		world.setBlockState(new BlockPos(x + 3, y + 10, z + 14), Blocks.AIR.getDefaultState(), 3);
		world.setBlockState(new BlockPos(x + 4, y + 10, z + 14), Blocks.AIR.getDefaultState(), 3);
		world.setBlockState(new BlockPos(x + 5, y + 10, z + 14), Blocks.AIR.getDefaultState(), 3);
		world.setBlockState(new BlockPos(x + 6, y + 10, z + 14), Blocks.AIR.getDefaultState(), 3);
		world.setBlockState(new BlockPos(x + 7, y + 10, z + 14), Blocks.AIR.getDefaultState(), 3);
		world.setBlockState(new BlockPos(x + 8, y + 10, z + 14), Blocks.AIR.getDefaultState(), 3);
		world.setBlockState(new BlockPos(x + 9, y + 10, z + 14), Blocks.AIR.getDefaultState(), 3);
		world.setBlockState(new BlockPos(x + 10, y + 10, z + 14), Blocks.AIR.getDefaultState(), 3);
		world.setBlockState(new BlockPos(x + 11, y + 10, z + 14), Blocks.AIR.getDefaultState(), 3);
		world.setBlockState(new BlockPos(x + 0, y + 11, z + 1), Blocks.AIR.getDefaultState(), 3);
		world.setBlockState(new BlockPos(x + 1, y + 11, z + 1), Blocks.AIR.getDefaultState(), 3);
		world.setBlockState(new BlockPos(x + 2, y + 11, z + 1), Blocks.AIR.getDefaultState(), 3);
		world.setBlockState(new BlockPos(x + 3, y + 11, z + 1), Blocks.AIR.getDefaultState(), 3);
		world.setBlockState(new BlockPos(x + 4, y + 11, z + 1), Blocks.AIR.getDefaultState(), 3);
		world.setBlockState(new BlockPos(x + 5, y + 11, z + 1), Blocks.AIR.getDefaultState(), 3);
		world.setBlockState(new BlockPos(x + 6, y + 11, z + 1), Blocks.AIR.getDefaultState(), 3);
		world.setBlockState(new BlockPos(x + 7, y + 11, z + 1), Blocks.AIR.getDefaultState(), 3);
		world.setBlockState(new BlockPos(x + 8, y + 11, z + 1), Blocks.AIR.getDefaultState(), 3);
		world.setBlockState(new BlockPos(x + 9, y + 11, z + 1), Blocks.AIR.getDefaultState(), 3);
		world.setBlockState(new BlockPos(x + 10, y + 11, z + 1), Blocks.AIR.getDefaultState(), 3);
		world.setBlockState(new BlockPos(x + 11, y + 11, z + 1), Blocks.AIR.getDefaultState(), 3);
		world.setBlockState(new BlockPos(x + 0, y + 11, z + 2), Blocks.AIR.getDefaultState(), 3);
		world.setBlockState(new BlockPos(x + 1, y + 11, z + 2), Blocks.OAK_FENCE.getDefaultState(), 3);
		world.setBlockState(new BlockPos(x + 2, y + 11, z + 2), Blocks.AIR.getDefaultState(), 3);
		world.setBlockState(new BlockPos(x + 3, y + 11, z + 2), Blocks.AIR.getDefaultState(), 3);
		world.setBlockState(new BlockPos(x + 4, y + 11, z + 2), Blocks.AIR.getDefaultState(), 3);
		world.setBlockState(new BlockPos(x + 5, y + 11, z + 2), Blocks.AIR.getDefaultState(), 3);
		world.setBlockState(new BlockPos(x + 6, y + 11, z + 2), Blocks.AIR.getDefaultState(), 3);
		world.setBlockState(new BlockPos(x + 7, y + 11, z + 2), Blocks.AIR.getDefaultState(), 3);
		world.setBlockState(new BlockPos(x + 8, y + 11, z + 2), Blocks.AIR.getDefaultState(), 3);
		world.setBlockState(new BlockPos(x + 9, y + 11, z + 2), Blocks.AIR.getDefaultState(), 3);
		world.setBlockState(new BlockPos(x + 10, y + 11, z + 2), Blocks.AIR.getDefaultState(), 3);
		world.setBlockState(new BlockPos(x + 11, y + 11, z + 2), Blocks.OAK_FENCE.getDefaultState(), 3);
		world.setBlockState(new BlockPos(x + 0, y + 11, z + 3), Blocks.AIR.getDefaultState(), 3);
		world.setBlockState(new BlockPos(x + 1, y + 11, z + 3), Blocks.AIR.getDefaultState(), 3);
		world.setBlockState(new BlockPos(x + 2, y + 11, z + 3), Blocks.AIR.getDefaultState(), 3);
		world.setBlockState(new BlockPos(x + 3, y + 11, z + 3), Blocks.AIR.getDefaultState(), 3);
		world.setBlockState(new BlockPos(x + 4, y + 11, z + 3), Blocks.AIR.getDefaultState(), 3);
		world.setBlockState(new BlockPos(x + 5, y + 11, z + 3), Blocks.OAK_FENCE.getDefaultState(), 3);
		world.setBlockState(new BlockPos(x + 6, y + 11, z + 3), Blocks.AIR.getDefaultState(), 3);
		world.setBlockState(new BlockPos(x + 7, y + 11, z + 3), Blocks.OAK_FENCE.getDefaultState(), 3);
		world.setBlockState(new BlockPos(x + 8, y + 11, z + 3), Blocks.AIR.getDefaultState(), 3);
		world.setBlockState(new BlockPos(x + 9, y + 11, z + 3), Blocks.AIR.getDefaultState(), 3);
		world.setBlockState(new BlockPos(x + 10, y + 11, z + 3), Blocks.AIR.getDefaultState(), 3);
		world.setBlockState(new BlockPos(x + 11, y + 11, z + 3), Blocks.AIR.getDefaultState(), 3);
		world.setBlockState(new BlockPos(x + 12, y + 11, z + 3), Blocks.AIR.getDefaultState(), 3);
		world.setBlockState(new BlockPos(x + 0, y + 11, z + 4), Blocks.AIR.getDefaultState(), 3);
		world.setBlockState(new BlockPos(x + 1, y + 11, z + 4), Blocks.AIR.getDefaultState(), 3);
		world.setBlockState(new BlockPos(x + 2, y + 11, z + 4), Blocks.AIR.getDefaultState(), 3);
		world.setBlockState(new BlockPos(x + 3, y + 11, z + 4), Blocks.AIR.getDefaultState(), 3);
		world.setBlockState(new BlockPos(x + 4, y + 11, z + 4), Blocks.AIR.getDefaultState(), 3);
		world.setBlockState(new BlockPos(x + 5, y + 11, z + 4), Blocks.AIR.getDefaultState(), 3);
		world.setBlockState(new BlockPos(x + 6, y + 11, z + 4), Blocks.AIR.getDefaultState(), 3);
		world.setBlockState(new BlockPos(x + 7, y + 11, z + 4), Blocks.AIR.getDefaultState(), 3);
